Workbook

Sheet Sheet2
B1: =B3/$K$3 -> 0.13220339 | C1: =C3/$K$3 -> 0.12881356 | D1: =D3/$K$3 -> 0.12881356 | E1: =E3/$K$3 -> 0.12542373 | F1: =F3/$K$3 -> 0.13898305 | G1: =G3/$K$3 -> 0.094915254 | H1: =H3/$K$3 -> 0.10169492 | I1: =I3/$K$3 -> 0.091525424 | J1: =J3/$K$3 -> 0.057627119 | O1: =O3/$X$3 -> 0.14731707 | P1: =P3/$X$3 -> 0.097560976 | Q1: =Q3/$X$3 -> 0.13170732 | R1: =R3/$X$3 -> 0.10439024 | S1: =S3/$X$3 -> 0.15219512 | T1: =T3/$X$3 -> 0.070243902 | U1: =U3/$X$3 -> 0.085853659 | V1: =V3/$X$3 -> 0.093658537 | W1: =W3/$X$3 -> 0.11707317
B2: Gen 1 | C2: Gen 2 | D2: Gen 3 | E2: Gen 4 | F2: Gen 5 | G2: Gen 6 | H2: Gen 7 | I2: Gen 8 | J2: Gen 9 | K2: Total | O2: Gen 1 | P2: Gen 2 | Q2: Gen 3 | R2: Gen 4 | S2: Gen 5 | T2: Gen 6 | U2: Gen 7 | V2: Gen 8 | W2: Gen 9 | X2: Total
B3: =L10 -> 39 | C3: =L11 -> 38 | D3: =L12 -> 38 | E3: =L13 -> 37 | F3: =L14 -> 41 | G3: =L15 -> 28 | H3: =L16 -> 30 | I3: =L17 -> 27 | J3: =L18 -> 17 | K3: =SUM(B3:J3) -> 295 | O3: 151 | P3: 100 | Q3: 135 | R3: 107 | S3: 156 | T3: 72 | U3: 88 | V3: 96 | W3: 120 | X3: =SUM(O3:W3) -> 1025
O4: =O6/$X$6 -> 0.14731707 | P4: =P6/$X$6 -> 0.097560976 | Q4: =Q6/$X$6 -> 0.13170732 | R4: =R6/$X$6 -> 0.10439024 | S4: =S6/$X$6 -> 0.15219512 | T4: =T6/$X$6 -> 0.070243902 | U4: =U6/$X$6 -> 0.085853659 | V4: =V6/$X$6 -> 0.093658537 | W4: =W6/$X$6 -> 0.11707317
B5: =B7/$K$3 -> 0.11864407 | C5: =C7/$K$3 -> 0.11864407 | D5: =D7/$K$3 -> 0.12542373 | E5: =E7/$K$3 -> 0.1220339 | F5: =F7/$K$3 -> 0.10847458 | G5: =G7/$K$3 -> 0.098305085 | H5: =H7/$K$3 -> 0.12542373 | I5: =I7/$K$3 -> 0.06779661 | ... L5: =L7/$K$3 -> 0.027118644 | O5: Gen 1 | P5: Gen 2 | Q5: Gen 3 | R5: Gen 4 | S5: Gen 5 | T5: Gen 6 | U5: Gen 7 | V5: Gen 8 | W5: Gen 9 | X5: Total
B6: Grass | C6: Fire | D6: Water | E6: Lightning | F6: Fighting | G6: Psychic | H6: Darkness | I6: Metal | J6: Colorless | K6: Trainers | L6: Energies | M6: Total | O6: =O3*40% -> 60.4 | P6: =P3*40% -> 40 | Q6: =Q3*40% -> 54 | R6: =R3*40% -> 42.8 | S6: =S3*40% -> 62.4 | T6: =T3*40% -> 28.8 | U6: =U3*40% -> 35.2 | V6: =V3*40% -> 38.4 | W6: =W3*40% -> 48 | X6: =SUM(O6:W6) -> 410
B7: =C19 -> 35 | C7: =D19 -> 35 | D7: =E19 -> 37 | E7: =F19 -> 36 | F7: =G19 -> 32 | G7: =H19 -> 29 | H7: =I19 -> 37 | I7: =J19 -> 20 | J7: =K19 -> 34 | K7: 36 | L7: 8 | M7: =SUM(B7:L7) -> 339 | N7: =M7+P14 -> 417 | O7: =O9/O6 -> 0.64569536 | P7: =P9/P6 -> 0.95 | Q7: =Q9/Q6 -> 0.7037037 | R7: =R9/R6 -> 0.86448598 | S7: =S9/S6 -> 0.65705128 | T7: =T9/T6 -> 0.97222222 | U7: =U9/U6 -> 0.85227273 | V7: =V9/V6 -> 0.703125 | W7: =W9/W6 -> 0.35416667
N8: =M7/N7 -> 0.81294964 | O8: Gen 1 | P8: Gen 2 | Q8: Gen 3 | R8: Gen 4 | S8: Gen 5 | T8: Gen 6 | U8: Gen 7 | V8: Gen 8 | W8: Gen 9 | X8: Total
B9: All | C9: Grass | D9: Fire | E9: Water | F9: Lightning | G9: Fighting | H9: Psychic | I9: Darkness | J9: Metal | K9: Colorless | L9: Total | O9: =L10 -> 39 | P9: =L11 -> 38 | Q9: =L12 -> 38 | R9: =L13 -> 37 | S9: =L14 -> 41 | T9: =L15 -> 28 | U9: =L16 -> 30 | V9: =L17 -> 27 | W9: =L18 -> 17 | X9: =SUM(O9:W9) -> 295 | Y9: {=X9+K7:L7} -> 331 | Z9: 303
B10: Gen 1 | C10: 2 | D10: 5 | E10: 9 | F10: 6 | G10: 4 | H10: 5 | I10: 5 | K10: 3 | L10: =SUM(C10:K10) -> 39 | M10: =L10/$L$19 -> 0.13220339 | N10: =L10-'1.7'!K10 -> 5 | O10: =O6-O9 -> 21.4 | P10: =P6-P9 -> 2 | Q10: =Q6-Q9 -> 16 | R10: =R6-R9 -> 5.8 | S10: =S6-S9 -> 21.4 | T10: =T6-T9 -> 0.8 | U10: =U6-U9 -> 5.2 | V10: =V6-V9 -> 11.4 | W10: =W6-W9 -> 31
B11: Gen 2 | C11: 4 | D11: 5 | E11: 3 | F11: 6 | G11: 5 | H11: 4 | I11: 4 | J11: 1 | K11: 6 | L11: =SUM(C11:K11) -> 38 | M11: =L11/$L$19 -> 0.12881356 | N11: =L11-'1.7'!K11 -> 6
B12: Gen 3 | C12: 8 | D12: 5 | E12: 6 | F12: 2 | G12: 3 | H12: 5 | I12: 2 | J12: 3 | K12: 4 | L12: =SUM(C12:K12) -> 38 | M12: =L12/$L$19 -> 0.12881356 | N12: =L12-'1.7'!K12 -> 1
B13: Gen 4 | C13: 8 | D13: 1 | E13: 4 | F13: 5 | G13: 3 | H13: 4 | I13: 7 | K13: 5 | L13: =SUM(C13:K13) -> 37 | M13: =L13/$L$19 -> 0.12542373 | N13: =L13-'1.7'!K13 -> 3
B14: Gen 5 | C14: 2 | D14: 9 | E14: 4 | F14: 6 | G14: 3 | H14: 2 | I14: 6 | J14: 6 | K14: 3 | L14: =SUM(C14:K14) -> 41 | M14: =L14/$L$19 -> 0.13898305 | N14: =L14-'1.7'!K14 -> 3 | O14: 56 | P14: 78 | Q14: =P14-O14 -> 22
B15: Gen 6 | C15: 2 | D15: 2 | E15: 5 | F15: 2 | G15: 3 | H15: 1 | I15: 6 | J15: 3 | K15: 4 | L15: =SUM(C15:K15) -> 28 | M15: =L15/$L$19 -> 0.094915254 | N15: =L15-'1.7'!K15 -> 5 | P15: =P14-10 -> 68 | Q15: 10
B16: Gen 7 | C16: 6 | D16: 3 | E16: 3 | F16: 4 | G16: 6 | H16: 3 | I16: 1 | K16: 4 | L16: =SUM(C16:K16) -> 30 | M16: =L16/$L$19 -> 0.10169492 | N16: =L16-'1.7'!K16 -> 0 | P16: 70 | Q16: 10
B17: Gen 8 | C17: 3 | D17: 2 | E17: 3 | F17: 3 | G17: 2 | H17: 3 | I17: 4 | J17: 4 | K17: 3 | L17: =SUM(C17:K17) -> 27 | M17: =L17/$L$19 -> 0.091525424 | N17: =L17-'1.7'!K17 -> 0 | P17: =P16/9 -> 7.7777778
B18: Gen 9 | C18: 0 | D18: 3 | E18: 0 | F18: 2 | G18: 3 | H18: 2 | I18: 2 | J18: 3 | K18: 2 | L18: =SUM(C18:K18) -> 17 | M18: =L18/$L$19 -> 0.057627119 | N18: =L18-'1.7'!K18 -> 6
B19: Total | C19: =SUM(C10:C18) -> 35 | D19: =SUM(D10:D18) -> 35 | E19: =SUM(E10:E18) -> 37 | F19: =SUM(F10:F18) -> 36 | G19: =SUM(G10:G18) -> 32 | H19: =SUM(H10:H18) -> 29 | I19: =SUM(I10:I18) -> 37 | J19: =SUM(J10:J18) -> 20 | ... L19: =SUM(L10:L18) -> 295
C20: =C19/$L$19 -> 0.11864407 | D20: =D19/$L$19 -> 0.11864407 | E20: =E19/$L$19 -> 0.12542373 | F20: =F19/$L$19 -> 0.1220339 | G20: =G19/$L$19 -> 0.10847458 | H20: =H19/$L$19 -> 0.098305085 | I20: =I19/$L$19 -> 0.12542373 | J20: =J19/$L$19 -> 0.06779661 | K20: =K19/$L$19 -> 0.11525424
C21: ='1.7'!C19+$P$17 -> 43.777778 | D21: ='1.7'!D19+$P$17 -> 39.777778 | E21: ='1.7'!E19+$P$17 -> 40.777778 | F21: ='1.7'!F19+$P$17 -> 40.777778 | G21: ='1.7'!G19+$P$17 -> 41.777778 | H21: ='1.7'!H19+$P$17 -> 40.777778 | I21: ='1.7'!I19+$P$17 -> 39.777778 | J21: =J19+$P$17 -> 27.777778 | K21: ='1.7'!J19+$P$17 -> 40.777778
C22: =C19-'1.7'!C19 -> -1 | D22: =D19-'1.7'!D19 -> 3 | E22: =E19-'1.7'!E19 -> 4 | F22: =F19-'1.7'!F19 -> 3 | G22: =G19-'1.7'!G19 -> -2 | H22: =H19-'1.7'!H19 -> -4 | I22: =I19-'1.7'!I19 -> 5 | K22: =K19-'1.7'!J19 -> 1 | L22: =SUM(C22:K22) -> 9
B23: Trainers
B24: 46
B25: =K7/$B$24 -> 0.7826087
P27: Input
P28: 31 | Q28: 255
P29: 30 | Q29: =(P29*255)/31 -> 246.77419 | S29: 2
P30: 27 | Q30: =(P30*255)/31 -> 222.09677 | S30: 3
P31: 24 | Q31: =(P31*255)/31 -> 197.41935 | S31: 6
Q32: Input
P33: 255 | Q33: 31
P34: =(Q34*31)/255 -> 30.14902 | Q34: 248
P35: =(Q35*31)/255 -> 33.796078 | Q35: 278
P36: =(Q36*31)/255 -> 0 | Q36: 0

Sheet Sheet4
B1: Average | H1: Highest | N1: Lowest | T1: General Average
B2: Grass Pokemon | C2: Basic | D2: Stage 1 | E2: Stage 2 | F2: Average | H2: Grass Pokemon | I2: Basic | J2: Stage 1 | K2: Stage 2 | L2: Average | N2: Grass Pokemon | O2: Basic | P2: Stage 1 | Q2: Stage 2 | R2: Average | T2: Pokemon | U2: Basic | V2: Stage 1 | W2: Stage 2
B3: HP | C3: =Sheet1!K3 -> 54.117647 | D3: =Sheet1!L3 -> 76.666667 | E3: =Sheet1!M3 -> 95 | F3: =AVERAGE(C3:E3) -> 75.261438 | H3: HP | I3: =Sheet1!K7 -> 70 | J3: =Sheet1!L7 -> 100 | K3: =Sheet1!M7 -> 100 | L3: =AVERAGE(I3:K3) -> 90 | N3: HP | O3: =Sheet1!K9 -> 40 | P3: =Sheet1!L9 -> 70 | Q3: =Sheet1!M9 -> 90 | R3: =AVERAGE(O3:Q3) -> 66.666667 | T3: HP | U3: =SUM(C3,C8,C13,C18,C23,C28,C33)/7 -> 53.986391 | V3: =SUM(D3,D8,D13,D18,D23,D28,D33)/7 -> 75.267066 | W3: =SUM(E3,E8,E13,E18,E23,E28,E33)/7 -> 102.44898
B4: RETREAT | C4: =Sheet1!K5 -> 1.1176471 | D4: =Sheet1!L5 -> 1.6666667 | E4: =Sheet1!M5 -> 1 | F4: =AVERAGE(C4:E4) -> 1.2614379 | H4: RETREAT | I4: =Sheet1!K11 -> 2 | J4: =Sheet1!L11 -> 4 | K4: =Sheet1!M11 -> 2 | L4: =AVERAGE(I4:K4) -> 2.6666667 | N4: RETREAT | O4: =Sheet1!K13 -> 0 | P4: =Sheet1!L13 -> 0 | Q4: =Sheet1!M13 -> 0 | R4: =AVERAGE(O4:Q4) -> 0 | T4: RETREAT | U4: =SUM(C4,C9,C14,C19,C24,C29,C34)/7 -> 1.1201514 | V4: =SUM(D4,D9,D14,D19,D24,D29,D34)/7 -> 1.6081395 | W4: =SUM(E4,E9,E14,E19,E24,E29,E34)/7 -> 1.935034
B6: Average | H6: Highest | N6: Lowest | T6: General MAX
B7: Fire Pokemon | C7: Basic | D7: Stage 1 | E7: Stage 2 | F7: Average | H7: Fire Pokemon | I7: Basic | J7: Stage 1 | K7: Stage 2 | L7: Average | N7: Fire Pokemon | O7: Basic | P7: Stage 1 | Q7: Stage 2 | R7: Average | T7: Pokemon | U7: Basic | V7: Stage 1 | W7: Stage 2
B8: HP | C8: =Sheet1!Y3 -> 60.666667 | D8: =Sheet1!Z3 -> 78.181818 | E8: =Sheet1!AA3 -> 108 | F8: =AVERAGE(C8:E8) -> 82.282828 | H8: HP | I8: =Sheet1!Y7 -> 100 | J8: =Sheet1!Z7 -> 90 | K8: =Sheet1!AA7 -> 120 | L8: =AVERAGE(I8:K8) -> 103.33333 | N8: HP | O8: =MIN(Sheet1!V3:V39) -> 30 | P8: =MIN(Sheet1!W3:W39) -> 70 | Q8: =MIN(Sheet1!X3:X39) -> 100 | R8: =AVERAGE(O8:Q8) -> 66.666667 | T8: HP | U8: =SUM(I3,I8,I13,I18,I23,I28,I33)/7 -> 81.428571 | V8: =SUM(J3,J8,J13,J18,J23,J28,J33)/7 -> 91.428571 | W8: =SUM(K3,K8,K13,K18,K23,K28,K33)/7 -> 112.85714
B9: RETREAT | C9: =Sheet1!Y5 -> 1.4 | D9: =Sheet1!Z5 -> 1.8181818 | E9: =Sheet1!AA5 -> 2.6 | F9: =AVERAGE(C9:E9) -> 1.9393939 | H9: RETREAT | I9: =Sheet1!Y11 -> 3 | J9: =Sheet1!Z11 -> 3 | K9: =Sheet1!AA11 -> 3 | L9: =AVERAGE(I9:K9) -> 3 | N9: RETREAT | O9: =MIN(Sheet1!V41:V77) -> 0 | P9: =MIN(Sheet1!W41:W77) -> 1 | Q9: =MIN(Sheet1!X41:X77) -> 2 | R9: =AVERAGE(O9:Q9) -> 1 | T9: RETREAT | U9: =SUM(I4,I9,I14,I19,I24,I29,I34)/7 -> 2.2857143 | V9: =SUM(J4,J9,J14,J19,J24,J29,J34)/7 -> 3 | W9: =SUM(K4,K9,K14,K19,K24,K29,K34)/7 -> 3
B11: Average | H11: Highest | N11: Lowest | T11: General MIN
B12: Water Pokemon | C12: Basic | D12: Stage 1 | E12: Stage 2 | F12: Average | H12: Water Pokemon | I12: Basic | J12: Stage 1 | K12: Stage 2 | L12: Average | N12: Water Pokemon | O12: Basic | P12: Stage 1 | Q12: Stage 2 | R12: Average | T12: Pokemon | U12: Basic | V12: Stage 1 | W12: Stage 2
B13: HP | C13: =Sheet1!AM3 -> 54.285714 | D13: =Sheet1!AN3 -> 75.714286 | E13: =Sheet1!AO3 -> 104 | F13: =AVERAGE(C13:E13) -> 78 | H13: HP | I13: =MAX(Sheet1!AJ3:AJ39) -> 80 | J13: =MAX(Sheet1!AK3:AK39) -> 90 | K13: =MAX(Sheet1!AL3:AL39) -> 110 | L13: =AVERAGE(I13:K13) -> 93.333333 | N13: HP | O13: =MIN(Sheet1!AJ3:AJ39) -> 40 | P13: =MIN(Sheet1!AK3:AK39) -> 60 | Q13: =MIN(Sheet1!AL3:AL39) -> 90 | R13: =AVERAGE(O13:Q13) -> 63.333333 | T13: HP | U13: =SUM(O3,O8,O13,O18,O23,O28,O33)/7 -> 32.857143 | V13: =SUM(P3,P8,P13,P18,P23,P28,P33)/7 -> 65.714286 | W13: =SUM(Q3,Q8,Q13,Q18,Q23,Q28,Q33)/7 -> 94.285714
B14: RETREAT | C14: =Sheet1!AM5 -> 1.0714286 | D14: =Sheet1!AN5 -> 1.5714286 | E14: =Sheet1!AO5 -> 2 | F14: =AVERAGE(C14:E14) -> 1.547619 | H14: RETREAT | I14: =MAX(Sheet1!AJ41:AJ77) -> 2 | J14: =MAX(Sheet1!AK41:AK77) -> 3 | K14: =MAX(Sheet1!AL41:AL77) -> 3 | L14: =AVERAGE(I14:K14) -> 2.6666667 | N14: RETREAT | O14: =MIN(Sheet1!AJ41:AJ77) -> 0 | P14: =MIN(Sheet1!AK41:AK77) -> 1 | Q14: =MIN(Sheet1!AL41:AL77) -> 1 | R14: =AVERAGE(O14:Q14) -> 0.66666667 | T14: RETREAT | U14: =SUM(O4,O9,O14,O19,O24,O29,O34)/7 -> 0 | V14: =SUM(P4,P9,P14,P19,P24,P29,P34)/7 -> 0.57142857 | W14: =SUM(Q4,Q9,Q14,Q19,Q24,Q29,Q34)/7 -> 0.85714286
B16: Average | H16: Highest | N16: Lowest | T16: How Many?
B17: Lightning Pokemon | C17: Basic | D17: Stage 1 | E17: Stage 2 | F17: Average | H17: Lightning Pokemon | I17: Basic | J17: Stage 1 | K17: Stage 2 | L17: Average | N17: Lightning Pokemon | O17: Basic | P17: Stage 1 | Q17: Stage 2 | R17: Average | T17: Pokemon | U17: Basic | V17: Stage 1 | W17: Stage 2
B18: HP | C18: =Sheet1!BA3 -> 53.333333 | D18: =Sheet1!BB3 -> 73 | E18: =Sheet1!BC3 -> 105 | F18: =AVERAGE(C18:E18) -> 77.111111 | H18: HP | I18: =MAX(Sheet1!AX3:AX39) -> 90 | J18: =MAX(Sheet1!AY3:AY39) -> 90 | K18: =MAX(Sheet1!AZ3:AZ39) -> 110 | L18: =AVERAGE(I18:K18) -> 96.666667 | N18: HP | O18: =MIN(Sheet1!AX3:AX39) -> 30 | P18: =MIN(Sheet1!AY3:AY39) -> 70 | Q18: =MIN(Sheet1!AZ3:AZ39) -> 100 | R18: =AVERAGE(O18:Q18) -> 66.666667 | T18: =SUM(U18:W18) -> 231 | U18: =SUM(Sheet1!G4,Sheet1!U4,Sheet1!AI4,Sheet1!AW4,Sheet1!BK4,Sheet1!BY4,Sheet1!CM4) -> 107 | V18: =SUM(Sheet1!G5,Sheet1!U5,Sheet1!AI5,Sheet1!AW5,Sheet1!BK5,Sheet1!BY5,Sheet1!CM5) -> 88 | W18: =SUM(Sheet1!G6,Sheet1!U6,Sheet1!AI6,Sheet1!AW6,Sheet1!BK6,Sheet1!BY6,Sheet1!CM6) -> 36
B19: RETREAT | C19: =Sheet1!BA5 -> 1.0555556 | D19: =Sheet1!BB5 -> 1.4 | E19: =Sheet1!BC5 -> 1.75 | F19: =AVERAGE(C19:E19) -> 1.4018519 | H19: RETREAT | I19: =MAX(Sheet1!AX41:AX77) -> 3 | J19: =MAX(Sheet1!AY41:AY77) -> 3 | K19: =MAX(Sheet1!AZ41:AZ77) -> 3 | L19: =AVERAGE(I19:K19) -> 3 | N19: RETREAT | O19: =MIN(Sheet1!AX41:AX77) -> 0 | P19: =MIN(Sheet1!AY41:AY77) -> 1 | Q19: =MIN(Sheet1!AZ41:AZ77) -> 1 | R19: =AVERAGE(O19:Q19) -> 0.66666667 | U19: =U18/$T$18 -> 0.46320346 | V19: =V18/$T$18 -> 0.38095238 | W19: =W18/$T$18 -> 0.15584416
B21: Average | H21: Highest | N21: Lowest
B22: Fighting Pokemon | C22: Basic | D22: Stage 1 | E22: Stage 2 | F22: Average | H22: Fighting Pokemon | I22: Basic | J22: Stage 1 | K22: Stage 2 | L22: Average | N22: Fighting Pokemon | O22: Basic | P22: Stage 1 | Q22: Stage 2 | R22: Average
B23: HP | C23: =Sheet1!BO3 -> 52.857143 | D23: =Sheet1!BP3 -> 75.384615 | E23: =Sheet1!BQ3 -> 107.14286 | F23: =AVERAGE(C23:E23) -> 78.461538 | H23: HP | I23: =MAX(Sheet1!BL3:BL39) -> 70 | J23: =MAX(Sheet1!BM3:BM39) -> 100 | K23: =MAX(Sheet1!BN3:BN39) -> 120 | L23: =AVERAGE(I23:K23) -> 96.666667 | N23: HP | O23: =MIN(Sheet1!BL3:BL39) -> 30 | P23: =MIN(Sheet1!BM3:BM39) -> 60 | Q23: =MIN(Sheet1!BN3:BN39) -> 100 | R23: =AVERAGE(O23:Q23) -> 63.333333
B24: RETREAT | C24: =Sheet1!BO5 -> 1.0714286 | D24: =Sheet1!BP5 -> 1.8461538 | E24: =Sheet1!BQ5 -> 2.4285714 | F24: =AVERAGE(C24:E24) -> 1.7820513 | H24: RETREAT | I24: =MAX(Sheet1!BL41:BL77) -> 2 | J24: =MAX(Sheet1!BM41:BM77) -> 3 | K24: =MAX(Sheet1!BN41:BN77) -> 4 | L24: =AVERAGE(I24:K24) -> 3 | N24: RETREAT | O24: =MIN(Sheet1!BL41:BL77) -> 0 | P24: =MIN(Sheet1!BM41:BM77) -> 1 | Q24: =MIN(Sheet1!BN41:BN77) -> 1 | R24: =AVERAGE(O24:Q24) -> 0.66666667
B26: Average | H26: Highest | N26: Lowest
B27: Psychic Pokemon | C27: Basic | D27: Stage 1 | E27: Stage 2 | F27: Average | H27: Psychic Pokemon | I27: Basic | J27: Stage 1 | K27: Stage 2 | L27: Average | N27: Psychic Pokemon | O27: Basic | P27: Stage 1 | Q27: Stage 2 | R27: Average
B28: HP | C28: =Sheet1!CC3 -> 51.875 | D28: =Sheet1!CD3 -> 73.636364 | E28: =Sheet1!CE3 -> 100 | F28: =AVERAGE(C28:E28) -> 75.170455 | H28: HP | I28: =Sheet1!CC7 -> 80 | J28: =Sheet1!CD7 -> 80 | K28: =Sheet1!CE7 -> 120 | L28: =AVERAGE(I28:K28) -> 93.333333 | N28: HP | O28: =Sheet1!CC9 -> 30 | P28: =Sheet1!CD9 -> 70 | Q28: =Sheet1!CE9 -> 90 | R28: =AVERAGE(O28:Q28) -> 63.333333
B29: RETREAT | C29: =Sheet1!CC5 -> 1.125 | D29: =Sheet1!CD5 -> 1.4545455 | E29: =Sheet1!CE5 -> 2.1666667 | F29: =AVERAGE(C29:E29) -> 1.5820707 | H29: RETREAT | I29: =Sheet1!CC11 -> 2 | J29: =Sheet1!CD11 -> 2 | K29: =Sheet1!CE11 -> 3 | L29: =AVERAGE(I29:K29) -> 2.3333333 | N29: RETREAT | O29: =Sheet1!CC13 -> 0 | P29: =Sheet1!CD13 -> 0 | Q29: =Sheet1!CE13 -> 1 | R29: =AVERAGE(O29:Q29) -> 0.33333333
B31: Average | H31: Highest | N31: Lowest
B32: Darkness Pokemon | C32: Basic | D32: Stage 1 | E32: Stage 2 | F32: Average | H32: Darkness Pokemon | I32: Basic | J32: Stage 1 | K32: Stage 2 | L32: Average | N32: Darkness Pokemon | O32: Basic | P32: Stage 1 | Q32: Stage 2 | R32: Average
B33: HP | C33: =Sheet1!CQ3 -> 50.769231 | D33: =Sheet1!CR3 -> 74.285714 | E33: =Sheet1!CS3 -> 98 | F33: =AVERAGE(C33:E33) -> 74.351648 | H33: HP | I33: =Sheet1!CQ7 -> 80 | J33: =Sheet1!CR7 -> 90 | K33: =Sheet1!CS7 -> 110 | L33: =AVERAGE(I33:K33) -> 93.333333 | N33: HP | O33: =Sheet1!CQ9 -> 30 | P33: =Sheet1!CR9 -> 60 | Q33: =Sheet1!CS9 -> 90 | R33: =AVERAGE(O33:Q33) -> 60
B34: RETREAT | C34: =Sheet1!CQ5 -> 1 | D34: =Sheet1!CR5 -> 1.5 | E34: =Sheet1!CS5 -> 1.6 | F34: =AVERAGE(C34:E34) -> 1.3666667 | H34: RETREAT | I34: =Sheet1!CQ11 -> 2 | J34: =Sheet1!CR11 -> 3 | K34: =Sheet1!CS11 -> 3 | L34: =AVERAGE(I34:K34) -> 2.6666667 | N34: RETREAT | O34: =Sheet1!CQ13 -> 0 | P34: =Sheet1!CR13 -> 0 | Q34: =Sheet1!CS13 -> 0 | R34: =AVERAGE(O34:Q34) -> 0

Sheet Sheet6
C2: WK | D2: RS
B3: GRASS | C3: =Sheet5!H3 -> 0 | D3: =Sheet5!I3 -> 5 | F3: FIRE | G3: {=_xlfn._xlws.SORT(C3:C9,,-1)} -> 23 | I3: FIRE | J3: {=_xlfn._xlws.SORT(D3:D9,,)} -> 1 | L3: =AVERAGE(G3,J3) -> 12 | M3: {=_xlfn._xlws.SORT(L3:L9,,-1)} -> 12
B4: FIRE | C4: =Sheet5!H8 -> 23 | D4: =Sheet5!I8 -> 1 | F4: LIGHTNING | G4: 4 | I4: DARKNESS | J4: 1 | L4: =AVERAGE(G4,J5) -> 3 | M4: 6
B5: WATER | C5: =Sheet5!H13 -> 3 | D5: =Sheet5!I13 -> 9 | F5: WATER | G5: 3 | I5: LIGHTNING | J5: 2 | L5: =AVERAGE(G5,J9) -> 6 | M5: 4.5
B6: LIGHTNING | C6: =Sheet5!H18 -> 4 | D6: =Sheet5!I18 -> 2 | F6: PSYCHIC | G6: 3 | I6: PSYCHIC | J6: 2 | L6: =AVERAGE(G6,J6) -> 2.5 | M6: 3
B7: FIGHTING | C7: =Sheet5!L3 -> 2 | D7: =Sheet5!M3 -> 7 | F7: FIGHTING | G7: 2 | I7: GRASS | J7: 5 | L7: =AVERAGE(G7,J8) -> 4.5 | M7: 2.5
B8: PSYCHIC | C8: =Sheet5!L8 -> 3 | D8: =Sheet5!M8 -> 2 | F8: DARKNESS | G8: 1 | I8: FIGHTING | J8: 7 | L8: =AVERAGE(G8,J4) -> 1 | M8: 2.5
B9: DARKNESS | C9: =Sheet5!L13 -> 1 | D9: =Sheet5!M13 -> 1 | F9: GRASS | G9: 0 | I9: WATER | J9: 9 | L9: =AVERAGE(G9,J7) -> 2.5 | M9: 1

Sheet Sheet3
C2: Total | D2: Common | E2: Uncommon | F2: Rare | G2: Energy | I2: Total | J2: Common | K2: Uncommon | L2: Rare | O2: Total | P2: Common | Q2: Uncommon | R2: Rare | U2: Total | V2: Common | W2: Uncommon | X2: Rare | AA2: Total | AB2: Common | AC2: Uncommon | AD2: Rare
B3: Colosseum | C3: =SUM(B7:B47)+G3 -> 65 | D3: =C8+C13+C18+C23+C28+C33+C38+C43+C48 -> 23 | E3: =D8+D13+D18+D23+D28+D33+D38+D43+D48 -> 21 | F3: =E8+E13+E18+E23+E28+E33+E38+E43+E48 -> 11 | G3: 7 | H3: Evolution | I3: =SUM(H7:H47)+M3 -> 63 | J3: =I8+I13+I18+I23+I28+I33+I38+I43+I48 -> 23 | K3: =J8+J13+J18+J23+J28+J33+J38+J43+J48 -> 24 | L3: =K8+K13+K18+K23+K28+K33+K38+K43+K48 -> 16 | N3: Mystery | O3: =SUM(N7:N47)+S3 -> 63 | P3: =O8+O13+O18+O23+O28+O33+O38+O43+O48 -> 20 | Q3: =P8+P13+P18+P23+P28+P33+P38+P43+P48 -> 26 | R3: =Q8+Q13+Q18+Q23+Q28+Q33+Q38+Q43+Q48 -> 18 | T3: Laboratory | U3: =SUM(T7:T47)+Y3 -> 61 | V3: =U8+U13+U18+U23+U28+U33+U38+U43+U48 -> 20 | W3: =V8+V13+V18+V23+V28+V33+V38+V43+V48 -> 20 | X3: =W8+W13+W18+W23+W28+W33+W38+W43+W48 -> 21 | Z3: Promo | AA3: 5 | AB3: =AA8+AA13+AA18+AA23+AA28+AA33+AA38+AA43+AA48 -> 0 | AC3: =AB8+AB13+AB18+AB23+AB28+AB33+AB38+AB43+AB48 -> 0 | AD3: 5
D4: =D3/$C$3 -> 0.35384615 | E4: =E3/$C$3 -> 0.32307692 | F4: =F3/$C$3 -> 0.16923077 | J4: =J3/$C$3 -> 0.35384615 | K4: =K3/$C$3 -> 0.36923077 | L4: =L3/$C$3 -> 0.24615385 | P4: =P3/$C$3 -> 0.30769231 | Q4: =Q3/$C$3 -> 0.4 | R4: =R3/$C$3 -> 0.27692308 | V4: =V3/$C$3 -> 0.30769231 | W4: =W3/$C$3 -> 0.30769231 | X4: =X3/$C$3 -> 0.32307692 | AB4: =AB3/$C$3 -> 0 | AC4: =AC3/$C$3 -> 0 | AD4: =AD3/$C$3 -> 0.076923077
B5: Colosseum | C5: Basic | D5: Stage 1 | E5: Stage 2 | H5: Evolution | I5: Basic | J5: Stage 1 | K5: Stage 2 | N5: =$N$3 -> Mystery | O5: Basic | P5: Stage 1 | Q5: Stage 2 | T5: =$N$3 -> Mystery | U5: Basic | V5: Stage 1 | W5: Stage 2
B6: Grass | C6: 4 | D6: 4 | E6: 1 | H6: Grass | I6: 5 | J6: 1 | K6: 1 | N6: Grass | O6: 5 | P6: 3 | Q6: 1 | T6: Grass | U6: 4 | V6: 4 | W6: 2
B7: =SUM(C6:E6) -> 9 | C7: Common | D7: Uncommon | E7: Rare | H7: =SUM(I6:K6) -> 7 | I7: Common | J7: Uncommon | K7: Rare | N7: =SUM(O6:Q6) -> 9 | O7: Common | P7: Uncommon | Q7: Rare | T7: =SUM(U6:W6) -> 10 | U7: Common | V7: Uncommon | W7: Rare
C8: 4 | D8: 4 | E8: 1 | I8: 4 | J8: 2 | K8: 1 | O8: 4 | P8: 2 | Q8: 3 | U8: 4 | V8: 4 | W8: 2 | Y8: =U3+O3+I3+C3+AA3 -> 257
C9: =C8/$B$7 -> 0.44444444 | D9: =D8/$B$7 -> 0.44444444 | E9: =E8/$B$7 -> 0.11111111
B10: Colosseum | C10: Basic | D10: Stage 1 | E10: Stage 2 | H10: Evolution | I10: Basic | J10: Stage 1 | K10: Stage 2 | N10: =$N$3 -> Mystery | O10: Basic | P10: Stage 1 | Q10: Stage 2 | T10: =$N$3 -> Mystery | U10: Basic | V10: Stage 1 | W10: Stage 2
B11: Fire | C11: 2 | D11: 2 | E11: 1 | H11: Fire | I11: 4 | J11: 3 | K11: 1 | N11: Fire | O11: 3 | P11: 3 | Q11: 1 | T11: Fire | U11: 3 | V11: 2 | W11: 1
B12: =SUM(C11:E11) -> 5 | C12: Common | D12: Uncommon | E12: Rare | H12: =SUM(I11:K11) -> 8 | I12: Common | J12: Uncommon | K12: Rare | N12: =SUM(O11:Q11) -> 7 | O12: Common | P12: Uncommon | Q12: Rare | T12: =SUM(U11:W11) -> 6 | U12: Common | V12: Uncommon | W12: Rare
C13: 2 | D13: 2 | E13: 1 | I13: 3 | J13: 3 | K13: 2 | O13: 2 | P13: 3 | Q13: 2 | U13: 2 | V13: 2 | W13: 2
C14: =C13/$B$12 -> 0.4 | D14: =D13/$B$12 -> 0.4 | E14: =E13/$B$12 -> 0.2
B15: Colosseum | C15: Basic | D15: Stage 1 | E15: Stage 2 | H15: Evolution | I15: Basic | J15: Stage 1 | K15: Stage 2 | N15: =$N$3 -> Mystery | O15: Basic | P15: Stage 1 | Q15: Stage 2 | T15: =$N$3 -> Mystery | U15: Basic | V15: Stage 1 | W15: Stage 2
B16: Water | C16: 3 | D16: 2 | E16: 1 | H16: Water | I16: 4 | J16: 4 | K16: 1 | N16: Water | O16: 2 | P16: 3 | Q16: 0 | T16: Water | U16: 2 | V16: 3 | W16: 1
B17: =SUM(C16:E16) -> 6 | C17: Common | D17: Uncommon | E17: Rare | H17: =SUM(I16:K16) -> 9 | I17: Common | J17: Uncommon | K17: Rare | N17: =SUM(O16:Q16) -> 5 | O17: Common | P17: Uncommon | Q17: Rare | T17: =SUM(U16:W16) -> 6 | U17: Common | V17: Uncommon | W17: Rare
C18: 2 | D18: 3 | E18: 1 | I18: 4 | J18: 4 | K18: 1 | O18: 2 | P18: 2 | Q18: 1 | U18: 2 | V18: 2 | W18: 2
C19: =C18/$B$17 -> 0.33333333 | D19: =D18/$B$17 -> 0.5 | E19: =E18/$B$17 -> 0.16666667
B20: Colosseum | C20: Basic | D20: Stage 1 | E20: Stage 2 | H20: Evolution | I20: Basic | J20: Stage 1 | K20: Stage 2 | N20: =$N$3 -> Mystery | O20: Basic | P20: Stage 1 | Q20: Stage 2 | T20: =$N$3 -> Mystery | U20: Basic | V20: Stage 1 | W20: Stage 2
B21: Lightning | C21: 2 | D21: 2 | E21: 1 | H21: Lightning | I21: 3 | J21: 4 | K21: 1 | N21: Lightning | O21: 3 | P21: 4 | Q21: 1 | T21: Lightning | U21: 4 | V21: 2 | W21: 2
B22: =SUM(C21:E21) -> 5 | C22: Common | D22: Uncommon | E22: Rare | H22: =SUM(I21:K21) -> 8 | I22: Common | J22: Uncommon | K22: Rare | N22: =SUM(O21:Q21) -> 8 | O22: Common | P22: Uncommon | Q22: Rare | T22: =SUM(U21:W21) -> 8 | U22: Common | V22: Uncommon | W22: Rare
C23: 2 | D23: 2 | E23: 1 | I23: 3 | J23: 4 | K23: 1 | O23: 2 | P23: 3 | Q23: 3 | U23: 2 | V23: 3 | W23: 3
C24: =C23/$B$22 -> 0.4 | D24: =D23/$B$22 -> 0.4 | E24: =E23/$B$22 -> 0.2
B25: Colosseum | C25: Basic | D25: Stage 1 | E25: Stage 2 | H25: Evolution | I25: Basic | J25: Stage 1 | K25: Stage 2 | N25: =$N$3 -> Mystery | O25: Basic | P25: Stage 1 | Q25: Stage 2 | T25: =$N$3 -> Mystery | U25: Basic | V25: Stage 1 | W25: Stage 2
B26: Fighting | C26: 2 | D26: 2 | E26: 1 | H26: Fighting | I26: 3 | J26: 4 | K26: 1 | N26: Fighting | O26: 4 | P26: 2 | Q26: 1 | T26: Fighting | U26: 2 | V26: 2 | W26: 2
B27: =SUM(C26:E26) -> 5 | C27: Common | D27: Uncommon | E27: Rare | H27: =SUM(I26:K26) -> 8 | I27: Common | J27: Uncommon | K27: Rare | N27: =SUM(O26:Q26) -> 7 | O27: Common | P27: Uncommon | Q27: Rare | T27: =SUM(U26:W26) -> 6 | U27: Common | V27: Uncommon | W27: Rare
C28: 2 | D28: 2 | E28: 1 | I28: 3 | J28: 4 | K28: 1 | O28: 2 | P28: 4 | Q28: 2 | U28: 2 | V28: 0 | W28: 4
C29: =C28/$B$27 -> 0.4 | D29: =D28/$B$27 -> 0.4 | E29: =E28/$B$27 -> 0.2
B30: Colosseum | C30: Basic | D30: Stage 1 | E30: Stage 2 | H30: Evolution | I30: Basic | J30: Stage 1 | K30: Stage 2 | N30: =$N$3 -> Mystery | O30: Basic | P30: Stage 1 | Q30: Stage 2 | T30: =$N$3 -> Mystery | U30: Basic | V30: Stage 1 | W30: Stage 2
B31: Psychic | C31: 2 | D31: 2 | E31: 1 | H31: Psychic | I31: 1 | J31: 2 | K31: 2 | N31: Psychic | O31: 2 | P31: 1 | Q31: 0 | T31: Psychic | U31: 6 | V31: 3 | W31: 1
B32: =SUM(C31:E31) -> 5 | C32: Common | D32: Uncommon | E32: Rare | H32: =SUM(I31:K31) -> 5 | I32: Common | J32: Uncommon | K32: Rare | N32: =SUM(O31:Q31) -> 3 | O32: Common | P32: Uncommon | Q32: Rare | T32: =SUM(U31:W31) -> 10 | U32: Common | V32: Uncommon | W32: Rare
C33: 2 | D33: 2 | E33: 1 | I33: 1 | J33: 1 | K33: 3 | O33: 0 | P33: 1 | Q33: 2 | U33: 3 | V33: 5 | W33: 2
C34: =C33/$B$32 -> 0.4 | D34: =D33/$B$32 -> 0.4 | E34: =E33/$B$32 -> 0.2
B35: Colosseum | C35: Basic | D35: Stage 1 | E35: Stage 2 | H35: Evolution | I35: Basic | J35: Stage 1 | K35: Stage 2 | N35: =$N$3 -> Mystery | O35: Basic | P35: Stage 1 | Q35: Stage 2 | T35: =$N$3 -> Mystery | U35: Basic | V35: Stage 1 | W35: Stage 2
B36: Darkness | C36: 1 | D36: 1 | E36: 1 | H36: Darkness | I36: 1 | J36: 1 | K36: 1 | N36: Darkness | O36: 3 | P36: 5 | Q36: 2 | T36: Darkness | U36: 0 | V36: 0 | W36: 0
B37: =SUM(C36:E36) -> 3 | C37: Common | D37: Uncommon | E37: Rare | H37: =SUM(I36:K36) -> 3 | I37: Common | J37: Uncommon | K37: Rare | N37: =SUM(O36:Q36) -> 10 | O37: Common | P37: Uncommon | Q37: Rare | T37: =SUM(U36:W36) -> 0 | U37: Common | V37: Uncommon | W37: Rare
C38: 0 | D38: 0 | E38: 0 | I38: 1 | J38: 0 | K38: 2 | O38: 3 | P38: 4 | Q38: 3 | U38: 0 | V38: 0 | W38: 0
C39: =C38/$B$37 -> 0 | D39: =D38/$B$37 -> 0 | E39: =E38/$B$37 -> 0
B40: Colosseum | C40: Basic | D40: Stage 1 | E40: Stage 2 | H40: Evolution | I40: Basic | J40: Stage 1 | K40: Stage 2 | N40: =$N$3 -> Mystery | O40: Basic | P40: Stage 1 | Q40: Stage 2 | T40: =$N$3 -> Mystery | U40: Basic | V40: Stage 1 | W40: Stage 2
B41: Colorless | C41: 4 | D41: 3 | E41: 1 | H41: Colorless | I41: 3 | J41: 3 | K41: 1 | N41: Colorless | O41: 8 | P41: 1 | Q41: 0 | T41: Colorless | U41: 4 | V41: 2 | W41: 2
...

Sheet Sheet1
A2: No. | B2: Grass Pokemon | C2: Stage | D2: HP | E2: Retreat | G2: Total | H2: Basic HP | I2: Stage 1 | J2: Stage 2 | K2: Average Basic | L2: Average Stage 1 | M2: Average Stage 2 | O2: No. | P2: Fire Pokemon | Q2: Stage | R2: HP | S2: Retreat | U2: Total | V2: Basic HP | W2: Stage 1 | X2: Stage 2 | Y2: Average Basic | Z2: Average Stage 1 | AA2: Average Stage 2 | AC2: No. | AD2: Water Pokemon | AE2: Stage | AF2: HP | AG2: Retreat | AI2: Total | AJ2: Basic HP | AK2: Stage 1 | AL2: Stage 2 | AM2: Average Basic | AN2: Average Stage 1 | AO2: Average Stage 2 | AQ2: No. | AR2: Lightning Pokemon | AS2: Stage | AT2: HP | AU2: Retreat | AW2: Total | AX2: Basic HP | AY2: Stage 1 | AZ2: Stage 2 | BA2: Average Basic | BB2: Average Stage 1 | BC2: Average Stage 2 | BE2: No. | BF2: Fighting Pokemon | BG2: Stage | BH2: HP | BI2: Retreat | BK2: Total | BL2: Basic HP | BM2: Stage 1 | BN2: Stage 2 | BO2: Average Basic | BP2: Average Stage 1 | BQ2: Average Stage 2 | BS2: No. | BT2: Psychic Pokemon | BU2: Stage | BV2: HP | BW2: Retreat | BY2: Total | BZ2: Basic HP | CA2: Stage 1 | CB2: Stage 2 | CC2: Average Basic | CD2: Average Stage 1 | CE2: Average Stage 2 | CG2: No. | CH2: Darkness Pokemon | CI2: Stage | CJ2: HP | CK2: Retreat | CM2: Total | CN2: Basic HP | CO2: Stage 1 | CP2: Stage 2 | CQ2: Average Basic | CR2: Average Stage 1 | CS2: Average Stage 2
A3: 1 | B3: Chikorita | C3: Basic | D3: 50 | E3: 1 | G3: =COUNT(A3:A38) -> 36 | H3: =IF(C3="Basic",D3,"") -> 50 | I3: =IF(C3="Stage 1",D3,"") | J3: =IF(C3="Stage 2",D3,"") | K3: =AVERAGE(H3:H39) -> 54.117647 | L3: =AVERAGE(I3:I39) -> 76.666667 | M3: =AVERAGE(J3:J39) -> 95 | O3: 1 | P3: Tepig | Q3: Basic | R3: 50 | S3: 1 | U3: =COUNT(O3:O39) -> 31 | V3: =IF(Q3="Basic",R3,"") -> 50 | W3: =IF(Q3="Stage 1",R3,"") | X3: =IF(Q3="Stage 2",R3,"") | Y3: =AVERAGE(V3:V39) -> 60.666667 | Z3: =AVERAGE(W3:W39) -> 78.181818 | AA3: =AVERAGE(X3:X39) -> 108 | AC3: 1 | AD3: Froakie | AE3: Basic | AF3: 50 | AG3: 1 | AI3: =COUNT(AC3:AC39) -> 33 | AJ3: =IF(AE3="Basic",AF3,"") -> 50 | AK3: =IF(AE3="Stage 1",AF3,"") | AL3: =IF(AE3="Stage 2",AF3,"") | AM3: =AVERAGE(AJ3:AJ39) -> 54.285714 | AN3: =AVERAGE(AK3:AK39) -> 75.714286 | AO3: =AVERAGE(AL3:AL39) -> 104 | AQ3: 1 | AR3: Blitzle | AS3: Basic | AT3: 40 | AU3: 1 | AW3: =COUNT(AQ3:AQ38) -> 32 | AX3: =IF(AS3="Basic",AT3,"") -> 40 | AY3: =IF(AS3="Stage 1",AT3,"") | AZ3: =IF(AS3="Stage 2",AT3,"") | BA3: =AVERAGE(AX3:AX39) -> 53.333333 | BB3: =AVERAGE(AY3:AY39) -> 73 | BC3: =AVERAGE(AZ3:AZ39) -> 105 | BE3: 1 | BF3: Meowth | BG3: Basic | BH3: 40 | BI3: 1 | BK3: =COUNT(BE3:BE39) -> 34 | BL3: =IF(BG3="Basic",BH3,"") -> 40 | BM3: =IF(BG3="Stage 1",BH3,"") | BN3: =IF(BG3="Stage 2",BH3,"") | BO3: =AVERAGE(BL3:BL39) -> 52.857143 | BP3: =AVERAGE(BM3:BM39) -> 75.384615 | BQ3: =AVERAGE(BN3:BN39) -> 107.14286 | BS3: 1 | BT3: Ralts | BU3: Basic | BV3: 50 | BW3: 1 | BY3: =COUNT(BS3:BS39) -> 33 | BZ3: =IF(BU3="Basic",BV3,"") -> 50 | CA3: =IF(BU3="Stage 1",BV3,"") | CB3: =IF(BU3="Stage 2",BV3,"") | CC3: =AVERAGE($BZ$3:$BZ$39) -> 51.875 | CD3: =AVERAGE(CA3:CA39) -> 73.636364 | CE3: =AVERAGE(CB3:CB39) -> 100 | CG3: 1 | CH3: Deino | CI3: Basic | CJ3: 50 | CK3: 1 | CM3: =COUNT(CG3:CG39) -> 32 | CN3: =IF(CI3="Basic",CJ3,"") -> 50 | CO3: =IF(CI3="Stage 1",CJ3,"") | CP3: =IF(CI3="Stage 2",CJ3,"") | CQ3: =AVERAGE(CN3:CN39) -> 50.769231 | CR3: =AVERAGE(CO3:CO39) -> 74.285714 | CS3: =AVERAGE(CP3:CP39) -> 98 | CU3: =SUM(CM3,BY3,BK3,AW3,AI3,U3,G3) -> 231
A4: 2 | B4: Bayleef | C4: Stage 1 | D4: 70 | E4: 2 | G4: =COUNTIF(C3:C39, "Basic") -> 17 | H4: =IF(C4="Basic",D4,"") | I4: =IF(C4="Stage 1",D4,"") -> 70 | J4: =IF(C4="Stage 2",D4,"") | K4: Average Retreat Basic | L4: Average Retreat Stage 1 | M4: Average Retreat Stage 2 | O4: 2 | P4: Pignite | Q4: Stage 1 | R4: 80 | S4: 2 | U4: =COUNTIF(Q3:Q39, "Basic") -> 15 | V4: =IF(Q4="Basic",R4,"") | W4: =IF(Q4="Stage 1",R4,"") -> 80 | X4: =IF(Q4="Stage 2",R4,"") | Y4: Average Retreat Basic | Z4: Average Retreat Stage 1 | AA4: Average Retreat Stage 2 | AC4: 2 | AD4: Frogadier | AE4: Stage 1 | AF4: 70 | AG4: 1 | AI4: =COUNTIF(AE3:AE39, "Basic") -> 14 | AJ4: =IF(AE4="Basic",AF4,"") | AK4: =IF(AE4="Stage 1",AF4,"") -> 70 | AL4: =IF(AE4="Stage 2",AF4,"") | AM4: Average Retreat Basic | AN4: Average Retreat Stage 1 | AO4: Average Retreat Stage 2 | AQ4: 2 | AR4: Zebstrika | AS4: Stage 1 | AT4: 70 | AU4: 1 | AW4: =COUNTIF(AS3:AS38, "Basic") -> 18 | AX4: =IF(AS4="Basic",AT4,"") | AY4: =IF(AS4="Stage 1",AT4,"") -> 70 | AZ4: =IF(AS4="Stage 2",AT4,"") | BA4: Average Retreat Basic | BB4: Average Retreat Stage 1 | BC4: Average Retreat Stage 2 | BE4: 2 | BF4: Perrserker | BG4: Stage 1 | BH4: 70 | BI4: 2 | BK4: =COUNTIF(BG3:BG39, "Basic") -> 14 | BL4: =IF(BG4="Basic",BH4,"") | BM4: =IF(BG4="Stage 1",BH4,"") -> 70 | BN4: =IF(BG4="Stage 2",BH4,"") | BO4: Average Retreat Basic | BP4: Average Retreat Stage 1 | BQ4: Average Retreat Stage 2 | BS4: 2 | BT4: Kirlia | BU4: Stage 1 | BV4: 70 | BW4: 1 | BY4: =COUNTIF(BU3:BU39, "Basic") -> 16 | BZ4: =IF(BU4="Basic",BV4,"") | CA4: =IF(BU4="Stage 1",BV4,"") -> 70 | CB4: =IF(BU4="Stage 2",BV4,"") | CC4: Average Retreat Basic | CD4: Average Retreat Stage 1 | CE4: Average Retreat Stage 2 | CG4: 2 | CH4: Zweilous | CI4: Stage 1 | CJ4: 80 | CK4: 2 | CM4: =COUNTIF(CI3:CI39, "Basic") -> 13 | CN4: =IF(CI4="Basic",CJ4,"") | CO4: =IF(CI4="Stage 1",CJ4,"") -> 80 | CP4: =IF(CI4="Stage 2",CJ4,"") | CQ4: Average Retreat Basic | CR4: Average Retreat Stage 1 | CS4: Average Retreat Stage 2
A5: 3 | B5: Meganium | C5: Stage 2 | D5: 100 | E5: 2 | G5: =COUNTIF(C3:C39, "Stage 1") -> 15 | H5: =IF(C5="Basic",D5,"") | I5: =IF(C5="Stage 1",D5,"") | J5: =IF(C5="Stage 2",D5,"") -> 100 | K5: =AVERAGE(H41:H77) -> 1.1176471 | L5: =AVERAGE(I41:I77) -> 1.6666667 | M5: =AVERAGE(J41:J77) -> 1 | O5: 3 | P5: Emboar | Q5: Stage 2 | R5: 120 | S5: 3 | U5: =COUNTIF(Q3:Q39, "Stage 1") -> 11 | V5: =IF(Q5="Basic",R5,"") | W5: =IF(Q5="Stage 1",R5,"") | X5: =IF(Q5="Stage 2",R5,"") -> 120 | Y5: =AVERAGE(V41:V77) -> 1.4 | Z5: =AVERAGE(W41:W77) -> 1.8181818 | AA5: =AVERAGE(X41:X77) -> 2.6 | AC5: 3 | AD5: Greninja | AE5: Stage 2 | AF5: 90 | AG5: 1 | AI5: =COUNTIF(AE3:AE39, "Stage 1") -> 14 | AJ5: =IF(AE5="Basic",AF5,"") | AK5: =IF(AE5="Stage 1",AF5,"") | AL5: =IF(AE5="Stage 2",AF5,"") -> 90 | AM5: =AVERAGE(AJ41:AJ77) -> 1.0714286 | AN5: =AVERAGE(AK41:AK77) -> 1.5714286 | AO5: =AVERAGE(AL41:AL77) -> 2 | AQ5: 3 | AR5: Heloptile | AS5: Basic | AT5: 50 | AU5: 1 | AW5: =COUNTIF(AS3:AS38, "Stage 1") -> 10 | AX5: =IF(AS5="Basic",AT5,"") -> 50 | AY5: =IF(AS5="Stage 1",AT5,"") | AZ5: =IF(AS5="Stage 2",AT5,"") | BA5: =AVERAGE(AX41:AX77) -> 1.0555556 | BB5: =AVERAGE(AY41:AY77) -> 1.4 | BC5: =AVERAGE(AZ41:AZ77) -> 1.75 | BE5: 3 | BF5: Silicobra | BG5: Basic | BH5: 50 | BI5: 1 | BK5: =COUNTIF(BG3:BG39, "Stage 1") -> 13 | BL5: =IF(BG5="Basic",BH5,"") -> 50 | BM5: =IF(BG5="Stage 1",BH5,"") | BN5: =IF(BG5="Stage 2",BH5,"") | BO5: =AVERAGE(BL41:BL77) -> 1.0714286 | BP5: =AVERAGE(BM41:BM77) -> 1.8461538 | BQ5: =AVERAGE(BN41:BN77) -> 2.4285714 | BS5: 3 | BT5: Gardevoir | BU5: Stage 2 | BV5: 100 | BW5: 2 | BY5: =COUNTIF(BU3:BU39, "Stage 1") -> 11 | BZ5: =IF(BU5="Basic",BV5,"") | CA5: =IF(BU5="Stage 1",BV5,"") | CB5: =IF(BU5="Stage 2",BV5,"") -> 100 | CC5: =AVERAGE(BZ41:BZ77) -> 1.125 | CD5: =AVERAGE(CA41:CA77) -> 1.4545455 | CE5: =AVERAGE(CB41:CB77) -> 2.1666667 | CG5: 3 | CH5: Hydreigon | CI5: Stage 2 | CJ5: 100 | CK5: 3 | CM5: =COUNTIF(CI3:CI39, "Stage 1") -> 14 | CN5: =IF(CI5="Basic",CJ5,"") | CO5: =IF(CI5="Stage 1",CJ5,"") | CP5: =IF(CI5="Stage 2",CJ5,"") -> 100 | CQ5: =AVERAGE(CN41:CN77) -> 1 | CR5: =AVERAGE(CO41:CO77) -> 1.5 | CS5: =AVERAGE(CP41:CP77) -> 1.6
A6: 4 | B6: Celebi | C6: Basic | D6: 70 | E6: 1 | G6: =COUNTIF(C3:C39, "Stage 2") -> 4 | H6: =IF(C6="Basic",D6,"") -> 70 | I6: =IF(C6="Stage 1",D6,"") | J6: =IF(C6="Stage 2",D6,"") | K6: Max Basic | L6: Max Stage 1 | M6: Max Stage 2 | O6: 4 | P6: Houndour | Q6: Basic | R6: 50 | S6: 1 | U6: =COUNTIF(Q3:Q39, "Stage 2") -> 5 | V6: =IF(Q6="Basic",R6,"") -> 50 | W6: =IF(Q6="Stage 1",R6,"") | X6: =IF(Q6="Stage 2",R6,"") | Y6: Max Basic | Z6: Max Stage 1 | AA6: Max Stage 2 | AC6: 4 | AD6: Buizel | AE6: Basic | AF6: 40 | AG6: 0 | AI6: =COUNTIF(AE3:AE39, "Stage 2") -> 5 | AJ6: =IF(AE6="Basic",AF6,"") -> 40 | AK6: =IF(AE6="Stage 1",AF6,"") | AL6: =IF(AE6="Stage 2",AF6,"") | AM6: Max Basic | AN6: Max Stage 1 | AO6: Max Stage 2 | AQ6: 4 | AR6: Heliolisk | AS6: Stage 1 | AT6: 70 | AU6: 1 | AW6: =COUNTIF(AS3:AS38, "Stage 2") -> 4 | AX6: =IF(AS6="Basic",AT6,"") | AY6: =IF(AS6="Stage 1",AT6,"") -> 70 | AZ6: =IF(AS6="Stage 2",AT6,"") | BA6: Max Basic | BB6: Max Stage 1 | BC6: Max Stage 2 | BE6: 4 | BF6: Sandaconda | BG6: Stage 1 | BH6: 80 | BI6: 2 | BK6: =COUNTIF(BG3:BG39, "Stage 2") -> 7 | BL6: =IF(BG6="Basic",BH6,"") | BM6: =IF(BG6="Stage 1",BH6,"") -> 80 | BN6: =IF(BG6="Stage 2",BH6,"") | BO6: Max Basic | BP6: Max Stage 1 | BQ6: Max Stage 2 | BS6: 4 | BT6: Inkay | BU6: Basic | BV6: 50 | BW6: 1 | BY6: =COUNTIF(BU3:BU39, "Stage 2") -> 6 | BZ6: =IF(BU6="Basic",BV6,"") -> 50 | CA6: =IF(BU6="Stage 1",BV6,"") | CB6: =IF(BU6="Stage 2",BV6,"") | CC6: Max Basic | CD6: Max Stage 1 | CE6: Max Stage 2 | CG6: 4 | CH6: Murkrow | CI6: Basic | CJ6: 50 | CK6: 1 | CM6: =COUNTIF(CI3:CI39, "Stage 2") -> 5 | CN6: =IF(CI6="Basic",CJ6,"") -> 50 | CO6: =IF(CI6="Stage 1",CJ6,"") | CP6: =IF(CI6="Stage 2",CJ6,"") | CQ6: Max Basic | CR6: Max Stage 1 | CS6: Max Stage 2
A7: 5 | B7: Wurmple | C7: Basic | D7: 40 | E7: 1 | G7: =SUM(G4:G6) -> 36 | H7: =IF(C7="Basic",D7,"") -> 40 | I7: =IF(C7="Stage 1",D7,"") | J7: =IF(C7="Stage 2",D7,"") | K7: =MAX(H$3:H$39) -> 70 | L7: =MAX(I$3:I$39) -> 100 | M7: =MAX(J$3:J$39) -> 100 | O7: 5 | P7: Houndoom | Q7: Stage 1 | R7: 70 | S7: 1 | U7: =SUM(U4:U6) -> 31 | V7: =IF(Q7="Basic",R7,"") | W7: =IF(Q7="Stage 1",R7,"") -> 70 | X7: =IF(Q7="Stage 2",R7,"") | Y7: =MAX(V$3:V$39) -> 100 | Z7: =MAX(W$3:W$39) -> 90 | AA7: =MAX(X$3:X$39) -> 120 | AC7: 5 | AD7: Floatzel | AE7: Stage 1 | AF7: 70 | AG7: 1 | AI7: =SUM(AI4:AI6) -> 33 | AJ7: =IF(AE7="Basic",AF7,"") | AK7: =IF(AE7="Stage 1",AF7,"") -> 70 | AL7: =IF(AE7="Stage 2",AF7,"") | AM7: =MAX(AJ$3:AJ$39) -> 80 | AN7: =MAX(AK$3:AK$39) -> 90 | AO7: =MAX(AL$3:AL$39) -> 110 | AQ7: 5 | AR7: Pincurchin | AS7: Basic | AT7: 70 | AU7: 2 | AW7: =SUM(AW4:AW6) -> 32 | AX7: =IF(AS7="Basic",AT7,"") -> 70 | AY7: =IF(AS7="Stage 1",AT7,"") | AZ7: =IF(AS7="Stage 2",AT7,"") | BA7: =MAX(AX$3:AX$39) -> 90 | BB7: =MAX(AY$3:AY$39) -> 90 | BC7: =MAX(AZ$3:AZ$39) -> 110 | BE7: 5 | BF7: Sandile | BG7: Basic | BH7: 50 | BI7: 1 | BK7: =SUM(BK4:BK6) -> 34 | BL7: =IF(BG7="Basic",BH7,"") -> 50 | BM7: =IF(BG7="Stage 1",BH7,"") | BN7: =IF(BG7="Stage 2",BH7,"") | BO7: =MAX(BL$3:BL$39) -> 70 | BP7: =MAX(BM$3:BM$39) -> 100 | BQ7: =MAX(BN$3:BN$39) -> 120 | BS7: 5 | BT7: Malamar | BU7: Stage 1 | BV7: 70 | BW7: 1 | BY7: =SUM(BY4:BY6) -> 33 | BZ7: =IF(BU7="Basic",BV7,"") | CA7: =IF(BU7="Stage 1",BV7,"") -> 70 | CB7: =IF(BU7="Stage 2",BV7,"") | CC7: =MAX(BZ$3:BZ$39) -> 80 | CD7: =MAX(CA$3:CA$39) -> 80 | CE7: =MAX(CB$3:CB$39) -> 120 | CG7: 5 | CH7: Honchkrow | CI7: Stage 1 | CJ7: 80 | CK7: 2 | CM7: =SUM(CM4:CM6) -> 32 | CN7: =IF(CI7="Basic",CJ7,"") | CO7: =IF(CI7="Stage 1",CJ7,"") -> 80 | CP7: =IF(CI7="Stage 2",CJ7,"") | CQ7: =MAX(CN$3:CN$39) -> 80 | CR7: =MAX(CO$3:CO$39) -> 90 | CS7: =MAX(CP$3:CP$39) -> 110
A8: 6 | B8: Silcoon | C8: Stage 1 | D8: 70 | E8: 2 | H8: =IF(C8="Basic",D8,"") | I8: =IF(C8="Stage 1",D8,"") -> 70 | J8: =IF(C8="Stage 2",D8,"") | K8: Min Basic | L8: Min Stage 1 | M8: Min Stage 2 | O8: 6 | P8: Delta Kingdra | Q8: Stage 2 | R8: 100 | S8: 2 | V8: =IF(Q8="Basic",R8,"") | W8: =IF(Q8="Stage 1",R8,"") | X8: =IF(Q8="Stage 2",R8,"") -> 100 | Y8: Min Basic | Z8: Min Stage 1 | AA8: Min Stage 2 | AC8: 6 | AD8: Bruxish | AE8: Basic | AF8: 60 | AG8: 1 | AJ8: =IF(AE8="Basic",AF8,"") -> 60 | AK8: =IF(AE8="Stage 1",AF8,"") | AL8: =IF(AE8="Stage 2",AF8,"") | AM8: Min Basic | AN8: Min Stage 1 | AO8: Min Stage 2 | AQ8: 6 | AR8: Shinx | AS8: Basic | AT8: 50 | AU8: 1 | AX8: =IF(AS8="Basic",AT8,"") -> 50 | AY8: =IF(AS8="Stage 1",AT8,"") | AZ8: =IF(AS8="Stage 2",AT8,"") | BA8: Min Basic | BB8: Min Stage 1 | BC8: Min Stage 2 | BE8: 6 | BF8: Krokorok | BG8: Stage 1 | BH8: 80 | BI8: 2 | BL8: =IF(BG8="Basic",BH8,"") | BM8: =IF(BG8="Stage 1",BH8,"") -> 80 | BN8: =IF(BG8="Stage 2",BH8,"") | BO8: Min Basic | BP8: Min Stage 1 | BQ8: Min Stage 2 | BS8: 6 | BT8: Duskull | BU8: Basic | BV8: 40 | BW8: 0 | BZ8: =IF(BU8="Basic",BV8,"") -> 40 | CA8: =IF(BU8="Stage 1",BV8,"") | CB8: =IF(BU8="Stage 2",BV8,"") | CC8: Min Basic | CD8: Min Stage 1 | CE8: Min Stage 2 | CG8: 6 | CH8: Skrelp | CI8: Basic | CJ8: 50 | CK8: 1 | CN8: =IF(CI8="Basic",CJ8,"") -> 50 | CO8: =IF(CI8="Stage 1",CJ8,"") | CP8: =IF(CI8="Stage 2",CJ8,"") | CQ8: Min Basic | CR8: Min Stage 1 | CS8: Min Stage 2
A9: 7 | B9: Beautifly | C9: Stage 2 | D9: 90 | E9: 0 | H9: =IF(C9="Basic",D9,"") | I9: =IF(C9="Stage 1",D9,"") | J9: =IF(C9="Stage 2",D9,"") -> 90 | K9: =MIN(H$3:H$39) -> 40 | L9: =MIN(I$3:I$39) -> 70 | M9: =MIN(J$3:J$39) -> 90 | O9: 7 | P9: Sizzlipede | Q9: Basic | R9: 40 | S9: 1 | V9: =IF(Q9="Basic",R9,"") -> 40 | W9: =IF(Q9="Stage 1",R9,"") | X9: =IF(Q9="Stage 2",R9,"") | Y9: =MIN(V$3:V$39) -> 30 | Z9: =MIN(W$3:W$39) -> 70 | AA9: =MIN(X$3:X$39) -> 100 | AC9: 7 | AD9: Tympole | AE9: Basic | AF9: 50 | AG9: 1 | AJ9: =IF(AE9="Basic",AF9,"") -> 50 | AK9: =IF(AE9="Stage 1",AF9,"") | AL9: =IF(AE9="Stage 2",AF9,"") | AM9: =MIN(AJ$3:AJ$39) -> 40 | AN9: =MIN(AK$3:AK$39) -> 60 | AO9: =MIN(AL$3:AL$39) -> 90 | AQ9: 7 | AR9: Luxio | AS9: Stage 1 | AT9: 70 | AU9: 1 | AX9: =IF(AS9="Basic",AT9,"") | AY9: =IF(AS9="Stage 1",AT9,"") -> 70 | AZ9: =IF(AS9="Stage 2",AT9,"") | BA9: =MIN(AX$3:AX$39) -> 30 | BB9: =MIN(AY$3:AY$39) -> 70 | BC9: =MIN(AZ$3:AZ$39) -> 100 | BE9: 7 | BF9: Krookodile | BG9: Stage 2 | BH9: 110 | BI9: 3 | BL9: =IF(BG9="Basic",BH9,"") | BM9: =IF(BG9="Stage 1",BH9,"") | BN9: =IF(BG9="Stage 2",BH9,"") -> 110 | BO9: =MIN(BL$3:BL$39) -> 30 | BP9: =MIN(BM$3:BM$39) -> 60 | BQ9: =MIN(BN$3:BN$39) -> 100 | BS9: 7 | BT9: Dusclobs | BU9: Stage 1 | BV9: 70 | BW9: 2 | BZ9: =IF(BU9="Basic",BV9,"") | CA9: =IF(BU9="Stage 1",BV9,"") -> 70 | CB9: =IF(BU9="Stage 2",BV9,"") | CC9: =MIN(BZ$3:BZ$39) -> 30 | CD9: =MIN(CA$3:CA$39) -> 70 | CE9: =MIN(CB$3:CB$39) -> 90 | CG9: 7 | CH9: Dragalge | CI9: Stage 1 | CJ9: 70 | CK9: 1 | CN9: =IF(CI9="Basic",CJ9,"") | CO9: =IF(CI9="Stage 1",CJ9,"") -> 70 | CP9: =IF(CI9="Stage 2",CJ9,"") | CQ9: =MIN(CN$3:CN$39) -> 30 | CR9: =MIN(CO$3:CO$39) -> 60 | CS9: =MIN(CP$3:CP$39) -> 90
A10: 8 | B10: Rowlet | C10: Basic | D10: 50 | E10: 0 | H10: =IF(C10="Basic",D10,"") -> 50 | I10: =IF(C10="Stage 1",D10,"") | J10: =IF(C10="Stage 2",D10,"") | K10: Max Retreat Basic | L10: Max Retreat Stage 1 | M10: Max Retreat Stage 2 | O10: 8 | P10: Centiskorch | Q10: Stage 1 | R10: 80 | S10: 2 | V10: =IF(Q10="Basic",R10,"") | W10: =IF(Q10="Stage 1",R10,"") -> 80 | X10: =IF(Q10="Stage 2",R10,"") | Y10: Max Retreat Basic | Z10: Max Retreat Stage 1 | AA10: Max Retreat Stage 2 | AC10: 8 | AD10: Palpitoad | AE10: Stage 1 | AF10: 80 | AG10: 2 | AJ10: =IF(AE10="Basic",AF10,"") | AK10: =IF(AE10="Stage 1",AF10,"") -> 80 | AL10: =IF(AE10="Stage 2",AF10,"") | AM10: Max Retreat Basic | AN10: Max Retreat Stage 1 | AO10: Max Retreat Stage 2 | AQ10: 8 | AR10: Luxray | AS10: Stage 2 | AT10: 100 | AU10: 1 | AX10: =IF(AS10="Basic",AT10,"") | AY10: =IF(AS10="Stage 1",AT10,"") | AZ10: =IF(AS10="Stage 2",AT10,"") -> 100 | BA10: Max Retreat Basic | BB10: Max Retreat Stage 1 | BC10: Max Retreat Stage 2 | BE10: 8 | BF10: Riolu | BG10: Basic | BH10: 50 | BI10: 1 | BL10: =IF(BG10="Basic",BH10,"") -> 50 | BM10: =IF(BG10="Stage 1",BH10,"") | BN10: =IF(BG10="Stage 2",BH10,"") | BO10: Max Retreat Basic | BP10: Max Retreat Stage 1 | BQ10: Max Retreat Stage 2 | BS10: 8 | BT10: Dusknoir | BU10: Stage 2 | BV10: 100 | BW10: 3 | BZ10: =IF(BU10="Basic",BV10,"") | CA10: =IF(BU10="Stage 1",BV10,"") | CB10: =IF(BU10="Stage 2",BV10,"") -> 100 | CC10: Max Retreat Basic | CD10: Max Retreat Stage 1 | CE10: Max Retreat Stage 2 | CG10: 8 | CH10: Cascoon | CI10: Stage 1 | CJ10: 70 | CK10: 1 | CN10: =IF(CI10="Basic",CJ10,"") | CO10: =IF(CI10="Stage 1",CJ10,"") -> 70 | CP10: =IF(CI10="Stage 2",CJ10,"") | CQ10: Max Retreat Basic | CR10: Max Retreat Stage 1 | CS10: Max Retreat Stage 2
A11: 9 | B11: Dartrix | C11: Stage 1 | D11: 70 | E11: 1 | H11: =IF(C11="Basic",D11,"") | I11: =IF(C11="Stage 1",D11,"") -> 70 | J11: =IF(C11="Stage 2",D11,"") | K11: =MAX(H41:H77) -> 2 | L11: =MAX(I41:I77) -> 4 | M11: =MAX(J41:J77) -> 2 | O11: 9 | P11: Darumaka | Q11: Basic | R11: 60 | S11: 2 | V11: =IF(Q11="Basic",R11,"") -> 60 | W11: =IF(Q11="Stage 1",R11,"") | X11: =IF(Q11="Stage 2",R11,"") | Y11: =MAX(V41:V77) -> 3 | Z11: =MAX(W41:W77) -> 3 | AA11: =MAX(X41:X77) -> 3 | AC11: 9 | AD11: Seismitoad | AE11: Stage 2 | AF11: 110 | AG11: 3 | AJ11: =IF(AE11="Basic",AF11,"") | AK11: =IF(AE11="Stage 1",AF11,"") | AL11: =IF(AE11="Stage 2",AF11,"") -> 110 | AM11: =MAX(AJ41:AJ77) -> 2 | AN11: =MAX(AK41:AK77) -> 3 | AO11: =MAX(AL41:AL77) -> 3 | AQ11: 9 | AR11: Emolga | AS11: Basic | AT11: 50 | AU11: 0 | AX11: =IF(AS11="Basic",AT11,"") -> 50 | AY11: =IF(AS11="Stage 1",AT11,"") | AZ11: =IF(AS11="Stage 2",AT11,"") | BA11: =MAX(AX41:AX77) -> 3 | BB11: =MAX(AY41:AY77) -> 3 | BC11: =MAX(AZ41:AZ77) -> 3 | BE11: 9 | BF11: Lucario | BG11: Stage 1 | BH11: 80 | BI11: 2 | BL11: =IF(BG11="Basic",BH11,"") | BM11: =IF(BG11="Stage 1",BH11,"") -> 80 | BN11: =IF(BG11="Stage 2",BH11,"") | BO11: =MAX(BL41:BL77) -> 2 | BP11: =MAX(BM41:BM77) -> 3 | BQ11: =MAX(BN41:BN77) -> 4 | BS11: 9 | BT11: Misdreavus | BU11: Basic | BV11: 50 | BW11: 1 | BZ11: =IF(BU11="Basic",BV11,"") -> 50 | CA11: =IF(BU11="Stage 1",BV11,"") | CB11: =IF(BU11="Stage 2",BV11,"") | CC11: =MAX(BZ41:BZ77) -> 2 | CD11: =MAX(CA41:CA77) -> 2 | CE11: =MAX(CB41:CB77) -> 3 | CG11: 9 | CH11: Dustox | CI11: Stage 2 | CJ11: 90 | CK11: 0 | CN11: =IF(CI11="Basic",CJ11,"") | CO11: =IF(CI11="Stage 1",CJ11,"") | CP11: =IF(CI11="Stage 2",CJ11,"") -> 90 | CQ11: =MAX(CN41:CN77) -> 2 | CR11: =MAX(CO41:CO77) -> 3 | CS11: =MAX(CP41:CP77) -> 3
A12: 10 | B12: Decidueye | C12: Stage 2 | D12: 90 | E12: 1 | H12: =IF(C12="Basic",D12,"") | I12: =IF(C12="Stage 1",D12,"") | J12: =IF(C12="Stage 2",D12,"") -> 90 | K12: Min Retreat Basic | L12: Min Retreat Stage 1 | M12: Min Retreat Stage 2 | O12: 10 | P12: Darmanitan | Q12: Stage 1 | R12: 90 | S12: 2 | V12: =IF(Q12="Basic",R12,"") | W12: =IF(Q12="Stage 1",R12,"") -> 90 | X12: =IF(Q12="Stage 2",R12,"") | Y12: Min Retreat Basic | Z12: Min Retreat Stage 1 | AA12: Min Retreat Stage 2 | AC12: 10 | AD12: Seel | AE12: Basic | AF12: 60 | AG12: 1 | AJ12: =IF(AE12="Basic",AF12,"") -> 60 | AK12: =IF(AE12="Stage 1",AF12,"") | AL12: =IF(AE12="Stage 2",AF12,"") | AM12: Min Retreat Basic | AN12: Min Retreat Stage 1 | AO12: Min Retreat Stage 2 | AQ12: 10 | AR12: Pichu | AS12: Basic | AT12: 30 | AU12: 0 | AX12: =IF(AS12="Basic",AT12,"") -> 30 | AY12: =IF(AS12="Stage 1",AT12,"") | AZ12: =IF(AS12="Stage 2",AT12,"") | BA12: Min Retreat Basic | BB12: Min Retreat Stage 1 | BC12: Min Retreat Stage 2 | BE12: 10 | BF12: Tyrogue | BG12: Basic | BH12: 30 | BI12: 0 | BL12: =IF(BG12="Basic",BH12,"") -> 30 | BM12: =IF(BG12="Stage 1",BH12,"") | BN12: =IF(BG12="Stage 2",BH12,"") | BO12: Min Retreat Basic | BP12: Min Retreat Stage 1 | BQ12: Min Retreat Stage 2 | BS12: 10 | BT12: Mismagius | BU12: Stage 1 | BV12: 70 | BW12: 1 | BZ12: =IF(BU12="Basic",BV12,"") | CA12: =IF(BU12="Stage 1",BV12,"") -> 70 | CB12: =IF(BU12="Stage 2",BV12,"") | CC12: Min Retreat Basic | CD12: Min Retreat Stage 1 | CE12: Min Retreat Stage 2 | CG12: 10 | CH12: Skorupi | CI12: Basic | CJ12: 60 | CK12: 2 | CN12: =IF(CI12="Basic",CJ12,"") -> 60 | CO12: =IF(CI12="Stage 1",CJ12,"") | CP12: =IF(CI12="Stage 2",CJ12,"") | CQ12: Min Retreat Basic | CR12: Min Retreat Stage 1 | CS12: Min Retreat Stage 2
A13: 11 | B13: Shellmet | C13: Basic | D13: 60 | E13: 2 | H13: =IF(C13="Basic",D13,"") -> 60 | I13: =IF(C13="Stage 1",D13,"") | J13: =IF(C13="Stage 2",D13,"") | K13: =MIN(H41:H77) -> 0 | L13: =MIN(I41:I77) -> 0 | M13: =MIN(J41:J77) -> 0 | O13: 11 | P13: Littleo | Q13: Basic | R13: 50 | S13: 1 | V13: =IF(Q13="Basic",R13,"") -> 50 | W13: =IF(Q13="Stage 1",R13,"") | X13: =IF(Q13="Stage 2",R13,"") | Y13: =MIN(V41:V77) -> 0 | Z13: =MIN(W41:W77) -> 1 | AA13: =MIN(X41:X77) -> 2 | AC13: 11 | AD13: Dewgong | AE13: Stage 1 | AF13: 80 | AG13: 2 | AJ13: =IF(AE13="Basic",AF13,"") | AK13: =IF(AE13="Stage 1",AF13,"") -> 80 | AL13: =IF(AE13="Stage 2",AF13,"") | AM13: =MIN(AJ41:AJ77) -> 0 | AN13: =MIN(AK41:AK77) -> 1 | AO13: =MIN(AL41:AL77) -> 1 | AQ13: 11 | AR13: Pikachu | AS13: Basic | AT13: 50 | AU13: 1 | AX13: =IF(AS13="Basic",AT13,"") -> 50 | AY13: =IF(AS13="Stage 1",AT13,"") | AZ13: =IF(AS13="Stage 2",AT13,"") | BA13: =MIN(AX41:AX77) -> 0 | BB13: =MIN(AY41:AY77) -> 1 | BC13: =MIN(AZ41:AZ77) -> 1 | BE13: 11 | BF13: Hitmonchan | BG13: Basic | BH13: 70 | BI13: 2 | BL13: =IF(BG13="Basic",BH13,"") -> 70 | BM13: =IF(BG13="Stage 1",BH13,"") | BN13: =IF(BG13="Stage 2",BH13,"") | BO13: =MIN(BL41:BL77) -> 0 | BP13: =MIN(BM41:BM77) -> 1 | BQ13: =MIN(BN41:BN77) -> 1 | BS13: 11 | BT13: Spiritomb | BU13: Basic | BV13: 50 | BW13: 2 | BZ13: =IF(BU13="Basic",BV13,"") -> 50 | CA13: =IF(BU13="Stage 1",BV13,"") | CB13: =IF(BU13="Stage 2",BV13,"") | CC13: =MIN(BZ41:BZ77) -> 0 | CD13: =MIN(CA41:CA77) -> 0 | CE13: =MIN(CB41:CB77) -> 1 | CG13: 11 | CH13: Drapion | CI13: Stage 1 | CJ13: 80 | CK13: 3 | CN13: =IF(CI13="Basic",CJ13,"") | CO13: =IF(CI13="Stage 1",CJ13,"") -> 80 | CP13: =IF(CI13="Stage 2",CJ13,"") | CQ13: =MIN(CN41:CN77) -> 0 | CR13: =MIN(CO41:CO77) -> 0 | CS13: =MIN(CP41:CP77) -> 0
A14: 12 | B14: Accelgor | C14: Stage 1 | D14: 80 | E14: 0 | H14: =IF(C14="Basic",D14,"") | I14: =IF(C14="Stage 1",D14,"") -> 80 | J14: =IF(C14="Stage 2",D14,"") | O14: 12 | P14: Pyroar | Q14: Stage 1 | R14: 70 | S14: 2 | V14: =IF(Q14="Basic",R14,"") | W14: =IF(Q14="Stage 1",R14,"") -> 70 | X14: =IF(Q14="Stage 2",R14,"") | AC14: 12 | AD14: Wigull | AE14: Basic | AF14: 50 | AG14: 1 | AJ14: =IF(AE14="Basic",AF14,"") -> 50 | AK14: =IF(AE14="Stage 1",AF14,"") | AL14: =IF(AE14="Stage 2",AF14,"") | AQ14: 12 | AR14: Raichu | AS14: Stage 1 | AT14: 70 | AU14: 2 | AX14: =IF(AS14="Basic",AT14,"") | AY14: =IF(AS14="Stage 1",AT14,"") -> 70 | AZ14: =IF(AS14="Stage 2",AT14,"") | BE14: 12 | BF14: Hitmonlee | BG14: Basic | BH14: 70 | BI14: 1 | BL14: =IF(BG14="Basic",BH14,"") -> 70 | BM14: =IF(BG14="Stage 1",BH14,"") | BN14: =IF(BG14="Stage 2",BH14,"") | BS14: 12 | BT14: Espeon | BU14: Stage 1 | BV14: 80 | BW14: 1 | BZ14: =IF(BU14="Basic",BV14,"") | CA14: =IF(BU14="Stage 1",BV14,"") -> 80 | CB14: =IF(BU14="Stage 2",BV14,"") | CG14: 12 | CH14: Zubat | CI14: Basic | CJ14: 40 | CK14: 0 | CN14: =IF(CI14="Basic",CJ14,"") -> 40 | CO14: =IF(CI14="Stage 1",CJ14,"") | CP14: =IF(CI14="Stage 2",CJ14,"")
A15: 13 | B15: Volbeat | C15: Basic | D15: 60 | E15: 1 | H15: =IF(C15="Basic",D15,"") -> 60 | I15: =IF(C15="Stage 1",D15,"") | J15: =IF(C15="Stage 2",D15,"") | O15: 13 | P15: Numel | Q15: Basic | R15: 50 | S15: 1 | V15: =IF(Q15="Basic",R15,"") -> 50 | W15: =IF(Q15="Stage 1",R15,"") | X15: =IF(Q15="Stage 2",R15,"") | AC15: 13 | AD15: Pelipper | AE15: Stage 1 | AF15: 80 | AG15: 2 | AJ15: =IF(AE15="Basic",AF15,"") | AK15: =IF(AE15="Stage 1",AF15,"") -> 80 | AL15: =IF(AE15="Stage 2",AF15,"") | AQ15: 13 | AR15: Magnemite | AS15: Basic | AT15: 40 | AU15: 1 | AX15: =IF(AS15="Basic",AT15,"") -> 40 | AY15: =IF(AS15="Stage 1",AT15,"") | AZ15: =IF(AS15="Stage 2",AT15,"") | BE15: 13 | BF15: Hitmontop | BG15: Basic | BH15: 70 | BI15: 1 | BL15: =IF(BG15="Basic",BH15,"") -> 70 | BM15: =IF(BG15="Stage 1",BH15,"") | BN15: =IF(BG15="Stage 2",BH15,"") | BS15: 13 | BT15: Abra | BU15: Basic | BV15: 40 | BW15: 1 | BZ15: =IF(BU15="Basic",BV15,"") -> 40 | CA15: =IF(BU15="Stage 1",BV15,"") | CB15: =IF(BU15="Stage 2",BV15,"") | CG15: 13 | CH15: Golbat | CI15: Stage 1 | CJ15: 60 | CK15: 0 | CN15: =IF(CI15="Basic",CJ15,"") | CO15: =IF(CI15="Stage 1",CJ15,"") -> 60 | CP15: =IF(CI15="Stage 2",CJ15,"")
A16: 14 | B16: Illumise | C16: Basic | D16: 60 | E16: 1 | H16: =IF(C16="Basic",D16,"") -> 60 | I16: =IF(C16="Stage 1",D16,"") | J16: =IF(C16="Stage 2",D16,"") | O16: 14 | P16: Camerupt | Q16: Stage 1 | R16: 80 | S16: 2 | V16: =IF(Q16="Basic",R16,"") | W16: =IF(Q16="Stage 1",R16,"") -> 80 | X16: =IF(Q16="Stage 2",R16,"") | AC16: 14 | AD16: Clauncher | AE16: Basic | AF16: 50 | AG16: 1 | AJ16: =IF(AE16="Basic",AF16,"") -> 50 | AK16: =IF(AE16="Stage 1",AF16,"") | AL16: =IF(AE16="Stage 2",AF16,"") | AQ16: 14 | AR16: Magneton | AS16: Stage 1 | AT16: 70 | AU16: 1 | AX16: =IF(AS16="Basic",AT16,"") | AY16: =IF(AS16="Stage 1",AT16,"") -> 70 | AZ16: =IF(AS16="Stage 2",AT16,"") | BE16: 14 | BF16: Trapinch | BG16: Basic | BH16: 50 | BI16: 1 | BL16: =IF(BG16="Basic",BH16,"") -> 50 | BM16: =IF(BG16="Stage 1",BH16,"") | BN16: =IF(BG16="Stage 2",BH16,"") | BS16: 14 | BT16: Kadabra | BU16: Stage 1 | BV16: 70 | BW16: 2 | BZ16: =IF(BU16="Basic",BV16,"") | CA16: =IF(BU16="Stage 1",BV16,"") -> 70 | CB16: =IF(BU16="Stage 2",BV16,"") | CG16: 14 | CH16: Crobat | CI16: Stage 2 | CJ16: 90 | CK16: 0 | CN16: =IF(CI16="Basic",CJ16,"") | CO16: =IF(CI16="Stage 1",CJ16,"") | CP16: =IF(CI16="Stage 2",CJ16,"") -> 90
A17: 15 | B17: Karrablast | C17: Basic | D17: 50 | E17: 1 | H17: =IF(C17="Basic",D17,"") -> 50 | I17: =IF(C17="Stage 1",D17,"") | J17: =IF(C17="Stage 2",D17,"") | O17: 15 | P17: Flareon | Q17: Stage 1 | R17: 70 | S17: 1 | V17: =IF(Q17="Basic",R17,"") | W17: =IF(Q17="Stage 1",R17,"") -> 70 | X17: =IF(Q17="Stage 2",R17,"") | AC17: 15 | AD17: Clawitzer | AE17: Stage 1 | AF17: 80 | AG17: 2 | AJ17: =IF(AE17="Basic",AF17,"") | AK17: =IF(AE17="Stage 1",AF17,"") -> 80 | AL17: =IF(AE17="Stage 2",AF17,"") | AQ17: 15 | AR17: Magnezone | AS17: Stage 2 | AT17: 110 | AU17: 2 | AX17: =IF(AS17="Basic",AT17,"") | AY17: =IF(AS17="Stage 1",AT17,"") | AZ17: =IF(AS17="Stage 2",AT17,"") -> 110 | BE17: 15 | BF17: Vibrava | BG17: Stage 1 | BH17: 70 | BI17: 1 | BL17: =IF(BG17="Basic",BH17,"") | BM17: =IF(BG17="Stage 1",BH17,"") -> 70 | BN17: =IF(BG17="Stage 2",BH17,"") | BS17: 15 | BT17: Alakazam | BU17: Stage 2 | BV17: 90 | BW17: 2 | BZ17: =IF(BU17="Basic",BV17,"") | CA17: =IF(BU17="Stage 1",BV17,"") | CB17: =IF(BU17="Stage 2",BV17,"") -> 90 | CG17: 15 | CH17: Croagunk | CI17: Basic | CJ17: 30 | CK17: 0 | CN17: =IF(CI17="Basic",CJ17,"") -> 30 | CO17: =IF(CI17="Stage 1",CJ17,"") | CP17: =IF(CI17="Stage 2",CJ17,"")
A18: 16 | B18: Escavalier | C18: Stage 1 | D18: 80 | E18: 2 | H18: =IF(C18="Basic",D18,"") | I18: =IF(C18="Stage 1",D18,"") -> 80 | J18: =IF(C18="Stage 2",D18,"") | O18: 16 | P18: Turtonator | Q18: Basic | R18: 80 | S18: 3 | V18: =IF(Q18="Basic",R18,"") -> 80 | W18: =IF(Q18="Stage 1",R18,"") | X18: =IF(Q18="Stage 2",R18,"") | AC18: 16 | AD18: Horsea | AE18: Basic | AF18: 40 | AG18: 1 | AJ18: =IF(AE18="Basic",AF18,"") -> 40 | AK18: =IF(AE18="Stage 1",AF18,"") | AL18: =IF(AE18="Stage 2",AF18,"") | AQ18: 16 | AR18: Toxel | AS18: Basic | AT18: 40 | AU18: 1 | AX18: =IF(AS18="Basic",AT18,"") -> 40 | AY18: =IF(AS18="Stage 1",AT18,"") | AZ18: =IF(AS18="Stage 2",AT18,"") | BE18: 16 | BF18: Flygon | BG18: Stage 2 | BH18: 100 | BI18: 1 | BL18: =IF(BG18="Basic",BH18,"") | BM18: =IF(BG18="Stage 1",BH18,"") | BN18: =IF(BG18="Stage 2",BH18,"") -> 100 | BS18: 16 | BT18: Mewtwo | BU18: Basic | BV18: 70 | BW18: 2 | BZ18: =IF(BU18="Basic",BV18,"") -> 70 | CA18: =IF(BU18="Stage 1",BV18,"") | CB18: =IF(BU18="Stage 2",BV18,"") | CG18: 16 | CH18: Toxicroak | CI18: Stage 1 | CJ18: 70 | CK18: 1 | CN18: =IF(CI18="Basic",CJ18,"") | CO18: =IF(CI18="Stage 1",CJ18,"") -> 70 | CP18: =IF(CI18="Stage 2",CJ18,"")
A19: 17 | B19: Applin | C19: Basic | D19: 50 | E19: 1 | H19: =IF(C19="Basic",D19,"") -> 50 | I19: =IF(C19="Stage 1",D19,"") | J19: =IF(C19="Stage 2",D19,"") | O19: 17 | P19: Entei | Q19: Basic | R19: 100 | S19: 2 | V19: =IF(Q19="Basic",R19,"") -> 100 | W19: =IF(Q19="Stage 1",R19,"") | X19: =IF(Q19="Stage 2",R19,"") | AC19: 17 | AD19: Seadra | AE19: Stage 1 | AF19: 70 | AG19: 1 | AJ19: =IF(AE19="Basic",AF19,"") | AK19: =IF(AE19="Stage 1",AF19,"") -> 70 | AL19: =IF(AE19="Stage 2",AF19,"") | AQ19: 17 | AR19: Toxtricity | AS19: Stage 1 | AT19: 70 | AU19: 1 | AX19: =IF(AS19="Basic",AT19,"") | AY19: =IF(AS19="Stage 1",AT19,"") -> 70 | AZ19: =IF(AS19="Stage 2",AT19,"") | BE19: 17 | BF19: Hawlucha | BG19: Basic | BH19: 60 | BI19: 1 | BL19: =IF(BG19="Basic",BH19,"") -> 60 | BM19: =IF(BG19="Stage 1",BH19,"") | BN19: =IF(BG19="Stage 2",BH19,"") | BS19: 17 | BT19: Mimiky | BU19: Basic | BV19: 50 | BW19: 1 | BZ19: =IF(BU19="Basic",BV19,"") -> 50 | CA19: =IF(BU19="Stage 1",BV19,"") | CB19: =IF(BU19="Stage 2",BV19,"") | CG19: 17 | CH19: Umbreon | CI19: Stage 1 | CJ19: 80 | CK19: 1 | CN19: =IF(CI19="Basic",CJ19,"") | CO19: =IF(CI19="Stage 1",CJ19,"") -> 80 | CP19: =IF(CI19="Stage 2",CJ19,"")
A20: 18 | B20: Flapple | C20: Stage 1 | D20: 70 | E20: 1 | H20: =IF(C20="Basic",D20,"") | I20: =IF(C20="Stage 1",D20,"") -> 70 | J20: =IF(C20="Stage 2",D20,"") | O20: 18 | P20: Fuecoco | Q20: Basic | R20: 60 | S20: 1 | V20: =IF(Q20="Basic",R20,"") -> 60 | W20: =IF(Q20="Stage 1",R20,"") | X20: =IF(Q20="Stage 2",R20,"") | AC20: 18 | AD20: Kingdra | AE20: Stage 2 | AF20: 100 | AG20: 1 | AJ20: =IF(AE20="Basic",AF20,"") | AK20: =IF(AE20="Stage 1",AF20,"") | AL20: =IF(AE20="Stage 2",AF20,"") -> 100 | AQ20: 18 | AR20: Elekid | AS20: Basic | AT20: 30 | AU20: 0 | AX20: =IF(AS20="Basic",AT20,"") -> 30 | AY20: =IF(AS20="Stage 1",AT20,"") | AZ20: =IF(AS20="Stage 2",AT20,"") | BE20: 18 | BF20: Larvitar | BG20: Basic | BH20: 50 | BI20: 1 | BL20: =IF(BG20="Basic",BH20,"") -> 50 | BM20: =IF(BG20="Stage 1",BH20,"") | BN20: =IF(BG20="Stage 2",BH20,"") | BS20: 18 | BT20: Mew | BU20: Basic | BV20: 50 | BW20: 1 | BZ20: =IF(BU20="Basic",BV20,"") -> 50 | CA20: =IF(BU20="Stage 1",BV20,"") | CB20: =IF(BU20="Stage 2",BV20,"") | CG20: 18 | CH20: Wooper | CI20: Basic | CJ20: 60 | CK20: 2 | CN20: =IF(CI20="Basic",CJ20,"") -> 60 | CO20: =IF(CI20="Stage 1",CJ20,"") | CP20: =IF(CI20="Stage 2",CJ20,"")
A21: 19 | B21: Appletune | C21: Stage 1 | D21: 80 | E21: 2 | H21: =IF(C21="Basic",D21,"") | I21: =IF(C21="Stage 1",D21,"") -> 80 | J21: =IF(C21="Stage 2",D21,"") | O21: 19 | P21: Crocalor | Q21: Stage 1 | R21: 80 | S21: 2 | V21: =IF(Q21="Basic",R21,"") | W21: =IF(Q21="Stage 1",R21,"") -> 80 | X21: =IF(Q21="Stage 2",R21,"") | AC21: 19 | AD21: Basculin | AE21: Basic | AF21: 50 | AG21: 1 | AJ21: =IF(AE21="Basic",AF21,"") -> 50 | AK21: =IF(AE21="Stage 1",AF21,"") | AL21: =IF(AE21="Stage 2",AF21,"") | AQ21: 19 | AR21: Electabuzz | AS21: Basic | AT21: 60 | AU21: 2 | AX21: =IF(AS21="Basic",AT21,"") -> 60 | AY21: =IF(AS21="Stage 1",AT21,"") | AZ21: =IF(AS21="Stage 2",AT21,"") | BE21: 19 | BF21: Pupitar | BG21: Stage 1 | BH21: 70 | BI21: 2 | BL21: =IF(BG21="Basic",BH21,"") | BM21: =IF(BG21="Stage 1",BH21,"") -> 70 | BN21: =IF(BG21="Stage 2",BH21,"") | BS21: 19 | BT21: Carbink | BU21: Basic | BV21: 60 | BW21: 1 | BZ21: =IF(BU21="Basic",BV21,"") -> 60 | CA21: =IF(BU21="Stage 1",BV21,"") | CB21: =IF(BU21="Stage 2",BV21,"") | CG21: 19 | CH21: Clodsire | CI21: Stage 1 | CJ21: 90 | CK21: 3 | CN21: =IF(CI21="Basic",CJ21,"") | CO21: =IF(CI21="Stage 1",CJ21,"") -> 90 | CP21: =IF(CI21="Stage 2",CJ21,"")
A22: 20 | B22: Shroomish | C22: Basic | D22: 40 | E22: 1 | H22: =IF(C22="Basic",D22,"") -> 40 | I22: =IF(C22="Stage 1",D22,"") | J22: =IF(C22="Stage 2",D22,"") | O22: 20 | P22: Skeledirge | Q22: Stage 2 | R22: 110 | S22: 3 | V22: =IF(Q22="Basic",R22,"") | W22: =IF(Q22="Stage 1",R22,"") | X22: =IF(Q22="Stage 2",R22,"") -> 110 | AC22: 20 | AD22: Basculigeon | AE22: Stage 1 | AF22: 70 | AG22: 2 | AJ22: =IF(AE22="Basic",AF22,"") | AK22: =IF(AE22="Stage 1",AF22,"") -> 70 | AL22: =IF(AE22="Stage 2",AF22,"") | AQ22: 20 | AR22: Electivire | AS22: Stage 1 | AT22: 90 | AU22: 3 | AX22: =IF(AS22="Basic",AT22,"") | AY22: =IF(AS22="Stage 1",AT22,"") -> 90 | AZ22: =IF(AS22="Stage 2",AT22,"") | BE22: 20 | BF22: Tyranitar | BG22: Stage 2 | BH22: 120 | BI22: 4 | BL22: =IF(BG22="Basic",BH22,"") | BM22: =IF(BG22="Stage 1",BH22,"") | BN22: =IF(BG22="Stage 2",BH22,"") -> 120 | BS22: 20 | BT22: Beldum | BU22: Basic | BV22: 50 | BW22: 1 | BZ22: =IF(BU22="Basic",BV22,"") -> 50 | CA22: =IF(BU22="Stage 1",BV22,"") | CB22: =IF(BU22="Stage 2",BV22,"") | CG22: 20 | CH22: Impidimp | CI22: Basic | CJ22: 40 | CK22: 1 | CN22: =IF(CI22="Basic",CJ22,"") -> 40 | CO22: =IF(CI22="Stage 1",CJ22,"") | CP22: =IF(CI22="Stage 2",CJ22,"")
A23: 21 | B23: Breloom | C23: Stage 1 | D23: 70 | E23: 1 | H23: =IF(C23="Basic",D23,"") | I23: =IF(C23="Stage 1",D23,"") -> 70 | J23: =IF(C23="Stage 2",D23,"") | O23: 21 | P23: Bagon | Q23: Basic | R23: 50 | S23: 1 | V23: =IF(Q23="Basic",R23,"") -> 50 | W23: =IF(Q23="Stage 1",R23,"") | X23: =IF(Q23="Stage 2",R23,"") | AC23: 21 | AD23: Dewpider | AE23: Basic | AF23: 50 | AG23: 1 | AJ23: =IF(AE23="Basic",AF23,"") -> 50 | AK23: =IF(AE23="Stage 1",AF23,"") | AL23: =IF(AE23="Stage 2",AF23,"") | AQ23: 21 | AR23: Electrike | AS23: Basic | AT23: 50 | AU23: 1 | AX23: =IF(AS23="Basic",AT23,"") -> 50 | AY23: =IF(AS23="Stage 1",AT23,"") | AZ23: =IF(AS23="Stage 2",AT23,"") | BE23: 21 | BF23: Cufant | BG23: Basic | BH23: 60 | BI23: 2 | BL23: =IF(BG23="Basic",BH23,"") -> 60 | BM23: =IF(BG23="Stage 1",BH23,"") | BN23: =IF(BG23="Stage 2",BH23,"") | BS23: 21 | BT23: Metang | BU23: Stage 1 | BV23: 80 | BW23: 2 | BZ23: =IF(BU23="Basic",BV23,"") | CA23: =IF(BU23="Stage 1",BV23,"") -> 80 | CB23: =IF(BU23="Stage 2",BV23,"") | CG23: 21 | CH23: Morgrem | CI23: Stage 1 | CJ23: 80 | CK23: 2 | CN23: =IF(CI23="Basic",CJ23,"") | CO23: =IF(CI23="Stage 1",CJ23,"") -> 80 | CP23: =IF(CI23="Stage 2",CJ23,"")
A24: 22 | B24: Yanma | C24: Basic | D24: 50 | E24: 1 | H24: =IF(C24="Basic",D24,"") -> 50 | I24: =IF(C24="Stage 1",D24,"") | J24: =IF(C24="Stage 2",D24,"") | O24: 22 | P24: Shelgon | Q24: Stage 1 | R24: 80 | S24: 2 | V24: =IF(Q24="Basic",R24,"") | W24: =IF(Q24="Stage 1",R24,"") -> 80 | X24: =IF(Q24="Stage 2",R24,"") | AC24: 22 | AD24: Araquanid | AE24: Stage 1 | AF24: 70 | AG24: 1 | AJ24: =IF(AE24="Basic",AF24,"") | AK24: =IF(AE24="Stage 1",AF24,"") -> 70 | AL24: =IF(AE24="Stage 2",AF24,"") | AQ24: 22 | AR24: Manectric | AS24: Stage 1 | AT24: 70 | AU24: 1 | AX24: =IF(AS24="Basic",AT24,"") | AY24: =IF(AS24="Stage 1",AT24,"") -> 70 | AZ24: =IF(AS24="Stage 2",AT24,"") | BE24: 22 | BF24: Copperajah | BG24: Stage 1 | BH24: 100 | BI24: 3 | BL24: =IF(BG24="Basic",BH24,"") | BM24: =IF(BG24="Stage 1",BH24,"") -> 100 | BN24: =IF(BG24="Stage 2",BH24,"") | BS24: 22 | BT24: Metagross | BU24: Stage 2 | BV24: 120 | BW24: 3 | BZ24: =IF(BU24="Basic",BV24,"") | CA24: =IF(BU24="Stage 1",BV24,"") | CB24: =IF(BU24="Stage 2",BV24,"") -> 120 | CG24: 22 | CH24: Grimmsnarl | CI24: Stage 2 | CJ24: 110 | CK24: 3 | CN24: =IF(CI24="Basic",CJ24,"") | CO24: =IF(CI24="Stage 1",CJ24,"") | CP24: =IF(CI24="Stage 2",CJ24,"") -> 110
